Workbook

Sheet schedule_ARAS
C1: WORK SCHEDULE VERSUS RESOURCE CHART
C2: PROJECT NAME: | D2: FİLYOS LİMANI TAHKİMAT İŞİ
C3: PROJECT DURATION: | D3: 36 | E3: Months
E4: Verim = | I4: 42217 | M4: 42248 | Q4: =+M4+31 -> 42279 | U4: =+Q4+31 -> 42310 | Y4: =+U4+31 -> 42341 | AC4: =+Y4+31 -> 42372 | AG4: =+AC4+31 -> 42403 | AK4: =+AG4+31 -> 42434 | AO4: =+AK4+31 -> 42465 | AS4: =+AO4+31 -> 42496 | AW4: =+AS4+31 -> 42527 | BA4: =+AW4+31 -> 42558 | BE4: =+BA4+31 -> 42589 | BI4: =+BE4+31 -> 42620 | BM4: =+BI4+31 -> 42651 | BQ4: =+BM4+31 -> 42682 | BU4: =+BQ4+31 -> 42713 | BY4: =+BU4+31 -> 42744 | CC4: =+BY4+31 -> 42775 | CG4: =+CC4+31 -> 42806 | CK4: =+CG4+31 -> 42837 | CO4: =+CK4+31 -> 42868 | CS4: =+CO4+31 -> 42899 | CW4: =+CS4+31 -> 42930 | DA4: =+CW4+31 -> 42961 | DE4: =+DA4+31 -> 42992
B5: S.NO. | C5: WORK DESCRIPTION | D5: UNIT | E5: QTY. | F5: Günlük Kapasite | G5: Günlük Verimli Kapasite | H5: Süre (Makine / Adam.Ay) | I5: Month-1 | M5: Month-2 | Q5: Month-3 | U5: Month-4 | Y5: Month-5 | AC5: Month-6 | AG5: Month-7 | AK5: Month-8 | AO5: Month-9 | AS5: Month-10 | AW5: Month-11 | BA5: Month-12 | BE5: Month-13 | BI5: Month-14 | BM5: Month-15 | BQ5: Month-16 | BU5: Month-17 | BY5: Month-18 | CC5: Month-19 | CG5: Month-20 | CK5: Month-21 | CO5: Month-22 | CS5: Month-23 | CW5: Month-24 | DA5: Month-25 | DE5: Month-26 | DI5: Month-27 | DM5: Month-28 | DQ5: Month-29 | DU5: Month-30 | DY5: Month-31 | EC5: Month-32 | EG5: Month-33 | EK5: Month-34 | EO5: Month-35 | ES5: Month-36 | EW5: Makine / Adam.Ay | EX5: Working per Day | EY5: Stand-by per Day | EZ5: Total Working | FA5: Total Stand-by
C6: Sözleşme İmzalanması
C7: Mobilizasyon
C8: Demobilizasyon
C10: Makine&Ekipman
EW11: =SUM(I11:DD11)/4 -> 0 | EZ11: =+EW11*EX11*28 -> 0 | FA11: =+EW11*EY11*30 -> 0
C12: Kurtuluş Kara | D12: Adet | E12: 1 | AG12: =+E12 -> 1 | AH12: =+E12 -> 1 | AI12: =+E12 -> 1 | AJ12: =+E12 -> 1 | AK12: =+E12 -> 1 | AL12: =+E12 -> 1 | AM12: =+E12 -> 1 | AN12: =+E12 -> 1 | AO12: =+E12 -> 1 | AP12: =+E12 -> 1 | AQ12: =+E12 -> 1 | AR12: =+E12 -> 1 | AS12: =+E12 -> 1 | AT12: =+E12 -> 1 | AU12: =+E12 -> 1 | AV12: =+E12 -> 1 | AW12: =+E12 -> 1 | AX12: =+E12 -> 1 | AY12: =+E12 -> 1 | AZ12: =+E12 -> 1 | BA12: =+E12 -> 1 | BB12: =+E12 -> 1 | BC12: =+E12 -> 1 | BD12: =+E12 -> 1 | BE12: =+E12 -> 1 | BF12: =+E12 -> 1 | BG12: =+E12 -> 1 | BH12: =+E12 -> 1 | BI12: =+E12 -> 1 | BJ12: =+E12 -> 1 | BK12: =+E12 -> 1 | BL12: =+E12 -> 1 | BM12: =+E12 -> 1 | BN12: =+E12 -> 1 | BO12: =+E12 -> 1 | BP12: =+E12 -> 1 | BQ12: =+AK12 -> 1 | BR12: =+AK12 -> 1 | BS12: =+AK12 -> 1 | BT12: =+AK12 -> 1 | BU12: =+AO12 -> 1 | BV12: =+AO12 -> 1 | BW12: =+AO12 -> 1 | BX12: =+AO12 -> 1 | BY12: =+AS12 -> 1 | BZ12: =+AS12 -> 1 | CA12: =+AS12 -> 1 | CB12: =+AS12 -> 1 | CC12: =+AW12 -> 1 | CD12: =+AW12 -> 1 | CE12: =+AW12 -> 1 | CF12: =+AW12 -> 1 | CG12: =+BA12 -> 1 | CH12: =+BA12 -> 1 | CI12: =+BA12 -> 1 | CJ12: =+BA12 -> 1 | CK12: =+BE12 -> 1 | CL12: =+BE12 -> 1 | CM12: =+BE12 -> 1 | CN12: =+BE12 -> 1 | CO12: =+BI12 -> 1 | CP12: =+BI12 -> 1 | CQ12: =+BI12 -> 1 | CR12: =+BI12 -> 1 | CS12: =+BM12 -> 1 | CT12: =+BM12 -> 1 | CU12: =+BM12 -> 1 | CV12: =+BM12 -> 1 | CW12: =+BQ12 -> 1 | CX12: =+BQ12 -> 1 | CY12: =+BQ12 -> 1 | CZ12: =+BQ12 -> 1 | DA12: =+BU12 -> 1 | DB12: =+BU12 -> 1 | DC12: =+BU12 -> 1 | DD12: =+BU12 -> 1 | DE12: =+BY12 -> 1 | DF12: =+BY12 -> 1 | DG12: =+BY12 -> 1 | DH12: =+BY12 -> 1 | DI12: =+CC12 -> 1 | DJ12: =+CC12 -> 1 | DK12: =+CC12 -> 1 | DL12: =+CC12 -> 1 | DM12: =+CG12 -> 1 | DN12: =+CG12 -> 1 | DO12: =+CG12 -> 1 | DP12: =+CG12 -> 1 | DQ12: =+CK12 -> 1 | DR12: =+CK12 -> 1 | DS12: =+CK12 -> 1 | DT12: =+CK12 -> 1 | DU12: =+CO12 -> 1 | DV12: =+CO12 -> 1 | DW12: =+CO12 -> 1 | DX12: =+CO12 -> 1 | DY12: =+CS12 -> 1 | DZ12: =+CS12 -> 1 | EA12: =+CS12 -> 1 | EB12: =+CS12 -> 1 | EC12: =+CW12 -> 1 | ED12: =+CW12 -> 1 | EE12: =+CW12 -> 1 | EF12: =+CW12 -> 1 | EG12: =+DA12 -> 1 | EH12: =+DA12 -> 1 | EI12: =+DA12 -> 1 | EJ12: =+DA12 -> 1 | EK12: =+DE12 -> 1 | EL12: =+DE12 -> 1 | EM12: =+DE12 -> 1 | EN12: =+DE12 -> 1 | EO12: =+DI12 -> 1 | EP12: =+DI12 -> 1 | EQ12: =+DI12 -> 1 | ER12: =+DI12 -> 1 | ES12: =+DM12 -> 1 | ET12: =+DM12 -> 1 | EU12: =+DM12 -> 1 | EV12: =+DM12 -> 1 | EW12: =SUM(I12:EV12)/4 -> 30 | EX12: 16 | EY12: =24-EX12 -> 8 | EZ12: =+EW12*EX12*28 -> 13440 | FA12: =+EW12*EY12*30 -> 7200
C13: Koparan | D13: Adet | E13: 1 | AG13: =+E13 -> 1 | AH13: =+E13 -> 1 | AI13: =+E13 -> 1 | AJ13: =+E13 -> 1 | AK13: =+E13 -> 1 | AL13: =+E13 -> 1 | AM13: =+E13 -> 1 | AN13: =+E13 -> 1 | AO13: =+E13 -> 1 | AP13: =+E13 -> 1 | AQ13: =+E13 -> 1 | AR13: =+E13 -> 1 | AS13: =+E13 -> 1 | AT13: =+E13 -> 1 | AU13: =+E13 -> 1 | AV13: =+E13 -> 1 | AW13: =+E13 -> 1 | AX13: =+E13 -> 1 | AY13: =+E13 -> 1 | AZ13: =+E13 -> 1 | BA13: =+E13 -> 1 | BB13: =+E13 -> 1 | BC13: =+E13 -> 1 | BD13: =+E13 -> 1 | BE13: =+E13 -> 1 | BF13: =+E13 -> 1 | BG13: =+E13 -> 1 | BH13: =+E13 -> 1 | BI13: =+E13 -> 1 | BJ13: =+E13 -> 1 | BK13: =+E13 -> 1 | BL13: =+E13 -> 1 | BM13: =+E13 -> 1 | BN13: =+E13 -> 1 | BO13: =+E13 -> 1 | BP13: =+E13 -> 1 | BQ13: =+AK13 -> 1 | BR13: =+AK13 -> 1 | BS13: =+AK13 -> 1 | BT13: =+AK13 -> 1 | BU13: =+AO13 -> 1 | BV13: =+AO13 -> 1 | BW13: =+AO13 -> 1 | BX13: =+AO13 -> 1 | BY13: =+AS13 -> 1 | BZ13: =+AS13 -> 1 | CA13: =+AS13 -> 1 | CB13: =+AS13 -> 1 | CC13: =+AW13 -> 1 | CD13: =+AW13 -> 1 | CE13: =+AW13 -> 1 | CF13: =+AW13 -> 1 | CG13: =+BA13 -> 1 | CH13: =+BA13 -> 1 | CI13: =+BA13 -> 1 | CJ13: =+BA13 -> 1 | CK13: =+BE13 -> 1 | CL13: =+BE13 -> 1 | CM13: =+BE13 -> 1 | CN13: =+BE13 -> 1 | CO13: =+BI13 -> 1 | CP13: =+BI13 -> 1 | CQ13: =+BI13 -> 1 | CR13: =+BI13 -> 1 | CS13: =+BM13 -> 1 | CT13: =+BM13 -> 1 | CU13: =+BM13 -> 1 | CV13: =+BM13 -> 1 | CW13: =+BQ13 -> 1 | CX13: =+BQ13 -> 1 | CY13: =+BQ13 -> 1 | CZ13: =+BQ13 -> 1 | DA13: =+BU13 -> 1 | DB13: =+BU13 -> 1 | DC13: =+BU13 -> 1 | DD13: =+BU13 -> 1 | DE13: =+BY13 -> 1 | DF13: =+BY13 -> 1 | DG13: =+BY13 -> 1 | DH13: =+BY13 -> 1 | DI13: =+CC13 -> 1 | DJ13: =+CC13 -> 1 | DK13: =+CC13 -> 1 | DL13: =+CC13 -> 1 | DM13: =+CG13 -> 1 | DN13: =+CG13 -> 1 | DO13: =+CG13 -> 1 | DP13: =+CG13 -> 1 | DQ13: =+CK13 -> 1 | DR13: =+CK13 -> 1 | DS13: =+CK13 -> 1 | DT13: =+CK13 -> 1 | DU13: =+CO13 -> 1 | DV13: =+CO13 -> 1 | DW13: =+CO13 -> 1 | DX13: =+CO13 -> 1 | DY13: =+CS13 -> 1 | DZ13: =+CS13 -> 1 | EA13: =+CS13 -> 1 | EB13: =+CS13 -> 1 | EC13: =+CW13 -> 1 | ED13: =+CW13 -> 1 | EE13: =+CW13 -> 1 | EF13: =+CW13 -> 1 | EG13: =+DA13 -> 1 | EH13: =+DA13 -> 1 | EI13: =+DA13 -> 1 | EJ13: =+DA13 -> 1 | EK13: =+DE13 -> 1 | EL13: =+DE13 -> 1 | EM13: =+DE13 -> 1 | EN13: =+DE13 -> 1 | EO13: =+DI13 -> 1 | EP13: =+DI13 -> 1 | EQ13: =+DI13 -> 1 | ER13: =+DI13 -> 1 | ES13: =+DM13 -> 1 | ET13: =+DM13 -> 1 | EU13: =+DM13 -> 1 | EV13: =+DM13 -> 1 | EW13: =SUM(I13:EV13)/4 -> 30 | EX13: 16 | EY13: =24-EX13 -> 8 | EZ13: =+EW13*EX13*28 -> 13440 | FA13: =+EW13*EY13*30 -> 7200
C14: Necem D-18 | D14: Adet | E14: 1 | AG14: =+E14 -> 1 | AH14: =+E14 -> 1 | AI14: =+E14 -> 1 | AJ14: =+E14 -> 1 | AK14: =+E14 -> 1 | AL14: =+E14 -> 1 | AM14: =+E14 -> 1 | AN14: =+E14 -> 1 | AO14: =+E14 -> 1 | AP14: =+E14 -> 1 | AQ14: =+E14 -> 1 | AR14: =+E14 -> 1 | AS14: =+E14 -> 1 | AT14: =+E14 -> 1 | AU14: =+E14 -> 1 | AV14: =+E14 -> 1 | AW14: =+E14 -> 1 | AX14: =+E14 -> 1 | AY14: =+E14 -> 1 | AZ14: =+E14 -> 1 | BA14: =+E14 -> 1 | BB14: =+E14 -> 1 | BC14: =+E14 -> 1 | BD14: =+E14 -> 1 | BE14: =+E14 -> 1 | BF14: =+E14 -> 1 | BG14: =+E14 -> 1 | BH14: =+E14 -> 1 | BI14: =+E14 -> 1 | BJ14: =+E14 -> 1 | BK14: =+E14 -> 1 | BL14: =+E14 -> 1 | BM14: =+E14 -> 1 | BN14: =+E14 -> 1 | BO14: =+E14 -> 1 | BP14: =+E14 -> 1 | BQ14: =+AK14 -> 1 | BR14: =+AK14 -> 1 | BS14: =+AK14 -> 1 | BT14: =+AK14 -> 1 | BU14: =+AO14 -> 1 | BV14: =+AO14 -> 1 | BW14: =+AO14 -> 1 | BX14: =+AO14 -> 1 | BY14: =+AS14 -> 1 | BZ14: =+AS14 -> 1 | CA14: =+AS14 -> 1 | CB14: =+AS14 -> 1 | CC14: =+AW14 -> 1 | CD14: =+AW14 -> 1 | CE14: =+AW14 -> 1 | CF14: =+AW14 -> 1 | CG14: =+BA14 -> 1 | CH14: =+BA14 -> 1 | CI14: =+BA14 -> 1 | CJ14: =+BA14 -> 1 | CK14: =+BE14 -> 1 | CL14: =+BE14 -> 1 | CM14: =+BE14 -> 1 | CN14: =+BE14 -> 1 | CO14: =+BI14 -> 1 | CP14: =+BI14 -> 1 | CQ14: =+BI14 -> 1 | CR14: =+BI14 -> 1 | CS14: =+BM14 -> 1 | CT14: =+BM14 -> 1 | CU14: =+BM14 -> 1 | CV14: =+BM14 -> 1 | CW14: =+BQ14 -> 1 | CX14: =+BQ14 -> 1 | CY14: =+BQ14 -> 1 | CZ14: =+BQ14 -> 1 | DA14: =+BU14 -> 1 | DB14: =+BU14 -> 1 | DC14: =+BU14 -> 1 | DD14: =+BU14 -> 1 | DE14: =+BY14 -> 1 | DF14: =+BY14 -> 1 | DG14: =+BY14 -> 1 | DH14: =+BY14 -> 1 | DI14: =+CC14 -> 1 | DJ14: =+CC14 -> 1 | DK14: =+CC14 -> 1 | DL14: =+CC14 -> 1 | DM14: =+CG14 -> 1 | DN14: =+CG14 -> 1 | DO14: =+CG14 -> 1 | DP14: =+CG14 -> 1 | DQ14: =+CK14 -> 1 | DR14: =+CK14 -> 1 | DS14: =+CK14 -> 1 | DT14: =+CK14 -> 1 | DU14: =+CO14 -> 1 | DV14: =+CO14 -> 1 | DW14: =+CO14 -> 1 | DX14: =+CO14 -> 1 | DY14: =+CS14 -> 1 | DZ14: =+CS14 -> 1 | EA14: =+CS14 -> 1 | EB14: =+CS14 -> 1 | EC14: =+CW14 -> 1 | ED14: =+CW14 -> 1 | EE14: =+CW14 -> 1 | EF14: =+CW14 -> 1 | EG14: =+DA14 -> 1 | EH14: =+DA14 -> 1 | EI14: =+DA14 -> 1 | EJ14: =+DA14 -> 1 | EK14: =+DE14 -> 1 | EL14: =+DE14 -> 1 | EM14: =+DE14 -> 1 | EN14: =+DE14 -> 1 | EO14: =+DI14 -> 1 | EP14: =+DI14 -> 1 | EQ14: =+DI14 -> 1 | ER14: =+DI14 -> 1 | ES14: =+DM14 -> 1 | ET14: =+DM14 -> 1 | EU14: =+DM14 -> 1 | EV14: =+DM14 -> 1 | EW14: =SUM(I14:EV14)/4 -> 30 | EX14: 16 | EY14: =24-EX14 -> 8 | EZ14: =+EW14*EX14*28 -> 13440 | FA14: =+EW14*EY14*30 -> 7200
C15: Alpaslan - II | D15: Adet | E15: 1 | G15: =+F15*$G$4 -> 0 | AG15: =+E15 -> 1 | AH15: =+E15 -> 1 | AI15: =+E15 -> 1 | AJ15: =+E15 -> 1 | AK15: =+E15 -> 1 | AL15: =+E15 -> 1 | AM15: =+E15 -> 1 | AN15: =+E15 -> 1 | AO15: =+E15 -> 1 | AP15: =+E15 -> 1 | AQ15: =+E15 -> 1 | AR15: =+E15 -> 1 | AS15: =+E15 -> 1 | AT15: =+E15 -> 1 | AU15: =+E15 -> 1 | AV15: =+E15 -> 1 | AW15: =+E15 -> 1 | AX15: =+E15 -> 1 | AY15: =+E15 -> 1 | AZ15: =+E15 -> 1 | BA15: =+E15 -> 1 | BB15: =+E15 -> 1 | BC15: =+E15 -> 1 | BD15: =+E15 -> 1 | BE15: =+E15 -> 1 | BF15: =+E15 -> 1 | BG15: =+E15 -> 1 | BH15: =+E15 -> 1 | BI15: =+E15 -> 1 | BJ15: =+E15 -> 1 | BK15: =+E15 -> 1 | BL15: =+E15 -> 1 | BM15: =+E15 -> 1 | BN15: =+E15 -> 1 | BO15: =+E15 -> 1 | BP15: =+E15 -> 1 | BQ15: =+AK15 -> 1 | BR15: =+AK15 -> 1 | BS15: =+AK15 -> 1 | BT15: =+AK15 -> 1 | BU15: =+AO15 -> 1 | BV15: =+AO15 -> 1 | BW15: =+AO15 -> 1 | BX15: =+AO15 -> 1 | BY15: =+AS15 -> 1 | BZ15: =+AS15 -> 1 | CA15: =+AS15 -> 1 | CB15: =+AS15 -> 1 | CC15: =+AW15 -> 1 | CD15: =+AW15 -> 1 | CE15: =+AW15 -> 1 | CF15: =+AW15 -> 1 | CG15: =+BA15 -> 1 | CH15: =+BA15 -> 1 | CI15: =+BA15 -> 1 | CJ15: =+BA15 -> 1 | CK15: =+BE15 -> 1 | CL15: =+BE15 -> 1 | CM15: =+BE15 -> 1 | CN15: =+BE15 -> 1 | CO15: =+BI15 -> 1 | CP15: =+BI15 -> 1 | CQ15: =+BI15 -> 1 | CR15: =+BI15 -> 1 | CS15: =+BM15 -> 1 | CT15: =+BM15 -> 1 | CU15: =+BM15 -> 1 | CV15: =+BM15 -> 1 | CW15: =+BQ15 -> 1 | CX15: =+BQ15 -> 1 | CY15: =+BQ15 -> 1 | CZ15: =+BQ15 -> 1 | DA15: =+BU15 -> 1 | DB15: =+BU15 -> 1 | DC15: =+BU15 -> 1 | DD15: =+BU15 -> 1 | DE15: =+BY15 -> 1 | DF15: =+BY15 -> 1 | DG15: =+BY15 -> 1 | DH15: =+BY15 -> 1 | DI15: =+CC15 -> 1 | DJ15: =+CC15 -> 1 | DK15: =+CC15 -> 1 | DL15: =+CC15 -> 1 | DM15: =+CG15 -> 1 | DN15: =+CG15 -> 1 | DO15: =+CG15 -> 1 | DP15: =+CG15 -> 1 | DQ15: =+CK15 -> 1 | DR15: =+CK15 -> 1 | DS15: =+CK15 -> 1 | DT15: =+CK15 -> 1 | DU15: =+CO15 -> 1 | DV15: =+CO15 -> 1 | DW15: =+CO15 -> 1 | DX15: =+CO15 -> 1 | DY15: =+CS15 -> 1 | DZ15: =+CS15 -> 1 | EA15: =+CS15 -> 1 | EB15: =+CS15 -> 1 | EC15: =+CW15 -> 1 | ED15: =+CW15 -> 1 | EE15: =+CW15 -> 1 | EF15: =+CW15 -> 1 | EG15: =+DA15 -> 1 | EH15: =+DA15 -> 1 | EI15: =+DA15 -> 1 | EJ15: =+DA15 -> 1 | EK15: =+DE15 -> 1 | EL15: =+DE15 -> 1 | EM15: =+DE15 -> 1 | EN15: =+DE15 -> 1 | EO15: =+DI15 -> 1 | EP15: =+DI15 -> 1 | EQ15: =+DI15 -> 1 | ER15: =+DI15 -> 1 | ES15: =+DM15 -> 1 | ET15: =+DM15 -> 1 | EU15: =+DM15 -> 1 | EV15: =+DM15 -> 1 | EW15: =SUM(I15:EV15)/4 -> 30 | EX15: 16 | EY15: =24-EX15 -> 8 | EZ15: =+EW15*EX15*28 -> 13440 | FA15: =+EW15*EY15*30 -> 7200
C16: Koca Seyit | D16: Adet | E16: 1 | G16: =+F16*$G$4 -> 0 | AG16: =+E16 -> 1 | AH16: =+E16 -> 1 | AI16: =+E16 -> 1 | AJ16: =+E16 -> 1 | AK16: =+E16 -> 1 | AL16: =+E16 -> 1 | AM16: =+E16 -> 1 | AN16: =+E16 -> 1 | AO16: =+E16 -> 1 | AP16: =+E16 -> 1 | AQ16: =+E16 -> 1 | AR16: =+E16 -> 1 | AS16: =+E16 -> 1 | AT16: =+E16 -> 1 | AU16: =+E16 -> 1 | AV16: =+E16 -> 1 | AW16: =+E16 -> 1 | AX16: =+E16 -> 1 | AY16: =+E16 -> 1 | AZ16: =+E16 -> 1 | BA16: =+E16 -> 1 | BB16: =+E16 -> 1 | BC16: =+E16 -> 1 | BD16: =+E16 -> 1 | BE16: =+E16 -> 1 | BF16: =+E16 -> 1 | BG16: =+E16 -> 1 | BH16: =+E16 -> 1 | BI16: =+E16 -> 1 | BJ16: =+E16 -> 1 | BK16: =+E16 -> 1 | BL16: =+E16 -> 1 | BM16: =+E16 -> 1 | BN16: =+E16 -> 1 | BO16: =+E16 -> 1 | BP16: =+E16 -> 1 | BQ16: =+AK16 -> 1 | BR16: =+AK16 -> 1 | BS16: =+AK16 -> 1 | BT16: =+AK16 -> 1 | BU16: =+AO16 -> 1 | BV16: =+AO16 -> 1 | BW16: =+AO16 -> 1 | BX16: =+AO16 -> 1 | BY16: =+AS16 -> 1 | BZ16: =+AS16 -> 1 | CA16: =+AS16 -> 1 | CB16: =+AS16 -> 1 | CC16: =+AW16 -> 1 | CD16: =+AW16 -> 1 | CE16: =+AW16 -> 1 | CF16: =+AW16 -> 1 | CG16: =+BA16 -> 1 | CH16: =+BA16 -> 1 | CI16: =+BA16 -> 1 | CJ16: =+BA16 -> 1 | CK16: =+BE16 -> 1 | CL16: =+BE16 -> 1 | CM16: =+BE16 -> 1 | CN16: =+BE16 -> 1 | CO16: =+BI16 -> 1 | CP16: =+BI16 -> 1 | CQ16: =+BI16 -> 1 | CR16: =+BI16 -> 1 | CS16: =+BM16 -> 1 | CT16: =+BM16 -> 1 | CU16: =+BM16 -> 1 | CV16: =+BM16 -> 1 | CW16: =+BQ16 -> 1 | CX16: =+BQ16 -> 1 | CY16: =+BQ16 -> 1 | CZ16: =+BQ16 -> 1 | DA16: =+BU16 -> 1 | DB16: =+BU16 -> 1 | DC16: =+BU16 -> 1 | DD16: =+BU16 -> 1 | DE16: =+BY16 -> 1 | DF16: =+BY16 -> 1 | DG16: =+BY16 -> 1 | DH16: =+BY16 -> 1 | DI16: =+CC16 -> 1 | DJ16: =+CC16 -> 1 | DK16: =+CC16 -> 1 | DL16: =+CC16 -> 1 | DM16: =+CG16 -> 1 | DN16: =+CG16 -> 1 | DO16: =+CG16 -> 1 | DP16: =+CG16 -> 1 | DQ16: =+CK16 -> 1 | DR16: =+CK16 -> 1 | DS16: =+CK16 -> 1 | DT16: =+CK16 -> 1 | DU16: =+CO16 -> 1 | DV16: =+CO16 -> 1 | DW16: =+CO16 -> 1 | DX16: =+CO16 -> 1 | DY16: =+CS16 -> 1 | DZ16: =+CS16 -> 1 | EA16: =+CS16 -> 1 | EB16: =+CS16 -> 1 | EC16: =+CW16 -> 1 | ED16: =+CW16 -> 1 | EE16: =+CW16 -> 1 | EF16: =+CW16 -> 1 | EG16: =+DA16 -> 1 | EH16: =+DA16 -> 1 | EI16: =+DA16 -> 1 | EJ16: =+DA16 -> 1 | EK16: =+DE16 -> 1 | EL16: =+DE16 -> 1 | EM16: =+DE16 -> 1 | EN16: =+DE16 -> 1 | EO16: =+DI16 -> 1 | EP16: =+DI16 -> 1 | EQ16: =+DI16 -> 1 | ER16: =+DI16 -> 1 | ES16: =+DM16 -> 1 | ET16: =+DM16 -> 1 | EU16: =+DM16 -> 1 | EV16: =+DM16 -> 1 | EW16: =SUM(I16:EV16)/4 -> 30 | EX16: 16 | EY16: =24-EX16 -> 8 | EZ16: =+EW16*EX16*28 -> 13440 | FA16: =+EW16*EY16*30 -> 7200
C17: Floating Crane 3 | D17: Adet | E17: 1 | AG17: =+E17 -> 1 | AH17: =+E17 -> 1 | AI17: =+E17 -> 1 | AJ17: =+E17 -> 1 | AK17: =+E17 -> 1 | AL17: =+E17 -> 1 | AM17: =+E17 -> 1 | AN17: =+E17 -> 1 | AO17: =+E17 -> 1 | AP17: =+E17 -> 1 | AQ17: =+E17 -> 1 | AR17: =+E17 -> 1 | AS17: =+E17 -> 1 | AT17: =+E17 -> 1 | AU17: =+E17 -> 1 | AV17: =+E17 -> 1 | AW17: =+E17 -> 1 | AX17: =+E17 -> 1 | AY17: =+E17 -> 1 | AZ17: =+E17 -> 1 | BA17: =+E17 -> 1 | BB17: =+E17 -> 1 | BC17: =+E17 -> 1 | BD17: =+E17 -> 1 | BE17: =+E17 -> 1 | BF17: =+E17 -> 1 | BG17: =+E17 -> 1 | BH17: =+E17 -> 1 | BI17: =+E17 -> 1 | BJ17: =+E17 -> 1 | BK17: =+E17 -> 1 | BL17: =+E17 -> 1 | BM17: =+E17 -> 1 | BN17: =+E17 -> 1 | BO17: =+E17 -> 1 | BP17: =+E17 -> 1 | BQ17: =+AK17 -> 1 | BR17: =+AK17 -> 1 | BS17: =+AK17 -> 1 | BT17: =+AK17 -> 1 | BU17: =+AO17 -> 1 | BV17: =+AO17 -> 1 | BW17: =+AO17 -> 1 | BX17: =+AO17 -> 1 | BY17: =+AS17 -> 1 | BZ17: =+AS17 -> 1 | CA17: =+AS17 -> 1 | CB17: =+AS17 -> 1 | CC17: =+AW17 -> 1 | CD17: =+AW17 -> 1 | CE17: =+AW17 -> 1 | CF17: =+AW17 -> 1 | CG17: =+BA17 -> 1 | CH17: =+BA17 -> 1 | CI17: =+BA17 -> 1 | CJ17: =+BA17 -> 1 | CK17: =+BE17 -> 1 | CL17: =+BE17 -> 1 | CM17: =+BE17 -> 1 | CN17: =+BE17 -> 1 | CO17: =+BI17 -> 1 | CP17: =+BI17 -> 1 | CQ17: =+BI17 -> 1 | CR17: =+BI17 -> 1 | CS17: =+BM17 -> 1 | CT17: =+BM17 -> 1 | CU17: =+BM17 -> 1 | CV17: =+BM17 -> 1 | CW17: =+BQ17 -> 1 | CX17: =+BQ17 -> 1 | CY17: =+BQ17 -> 1 | CZ17: =+BQ17 -> 1 | DA17: =+BU17 -> 1 | DB17: =+BU17 -> 1 | DC17: =+BU17 -> 1 | DD17: =+BU17 -> 1 | DE17: =+BY17 -> 1 | DF17: =+BY17 -> 1 | DG17: =+BY17 -> 1 | DH17: =+BY17 -> 1 | DI17: =+CC17 -> 1 | DJ17: =+CC17 -> 1 | DK17: =+CC17 -> 1 | DL17: =+CC17 -> 1 | DM17: =+CG17 -> 1 | DN17: =+CG17 -> 1 | DO17: =+CG17 -> 1 | DP17: =+CG17 -> 1 | DQ17: =+CK17 -> 1 | DR17: =+CK17 -> 1 | DS17: =+CK17 -> 1 | DT17: =+CK17 -> 1 | DU17: =+CO17 -> 1 | DV17: =+CO17 -> 1 | DW17: =+CO17 -> 1 | DX17: =+CO17 -> 1 | DY17: =+CS17 -> 1 | DZ17: =+CS17 -> 1 | EA17: =+CS17 -> 1 | EB17: =+CS17 -> 1 | EC17: =+CW17 -> 1 | ED17: =+CW17 -> 1 | EE17: =+CW17 -> 1 | EF17: =+CW17 -> 1 | EG17: =+DA17 -> 1 | EH17: =+DA17 -> 1 | EI17: =+DA17 -> 1 | EJ17: =+DA17 -> 1 | EK17: =+DE17 -> 1 | EL17: =+DE17 -> 1 | EM17: =+DE17 -> 1 | EN17: =+DE17 -> 1 | EO17: =+DI17 -> 1 | EP17: =+DI17 -> 1 | EQ17: =+DI17 -> 1 | ER17: =+DI17 -> 1 | ES17: =+DM17 -> 1 | ET17: =+DM17 -> 1 | EU17: =+DM17 -> 1 | EV17: =+DM17 -> 1 | EW17: =SUM(I17:EV17)/4 -> 30 | EX17: 16 | EY17: =24-EX17 -> 8 | EZ17: =+EW17*EX17*28 -> 13440 | FA17: =+EW17*EY17*30 -> 7200
C18: Midia 5 | D18: Adet | E18: 1 | AG18: =+E18 -> 1 | AH18: =+E18 -> 1 | AI18: =+E18 -> 1 | AJ18: =+E18 -> 1 | AK18: =+E18 -> 1 | AL18: =+E18 -> 1 | AM18: =+E18 -> 1 | AN18: =+E18 -> 1 | AO18: =+E18 -> 1 | AP18: =+E18 -> 1 | AQ18: =+E18 -> 1 | AR18: =+E18 -> 1 | AS18: =+E18 -> 1 | AT18: =+E18 -> 1 | AU18: =+E18 -> 1 | AV18: =+E18 -> 1 | AW18: =+E18 -> 1 | AX18: =+E18 -> 1 | AY18: =+E18 -> 1 | AZ18: =+E18 -> 1 | BA18: =+E18 -> 1 | BB18: =+E18 -> 1 | BC18: =+E18 -> 1 | BD18: =+E18 -> 1 | BE18: =+E18 -> 1 | BF18: =+E18 -> 1 | BG18: =+E18 -> 1 | BH18: =+E18 -> 1 | BI18: =+E18 -> 1 | BJ18: =+E18 -> 1 | BK18: =+E18 -> 1 | BL18: =+E18 -> 1 | BM18: =+E18 -> 1 | BN18: =+E18 -> 1 | BO18: =+E18 -> 1 | BP18: =+E18 -> 1 | BQ18: =+AK18 -> 1 | BR18: =+AK18 -> 1 | BS18: =+AK18 -> 1 | BT18: =+AK18 -> 1 | BU18: =+AO18 -> 1 | BV18: =+AO18 -> 1 | BW18: =+AO18 -> 1 | BX18: =+AO18 -> 1 | BY18: =+AS18 -> 1 | BZ18: =+AS18 -> 1 | CA18: =+AS18 -> 1 | CB18: =+AS18 -> 1 | CC18: =+AW18 -> 1 | CD18: =+AW18 -> 1 | CE18: =+AW18 -> 1 | CF18: =+AW18 -> 1 | CG18: =+BA18 -> 1 | CH18: =+BA18 -> 1 | CI18: =+BA18 -> 1 | CJ18: =+BA18 -> 1 | CK18: =+BE18 -> 1 | CL18: =+BE18 -> 1 | CM18: =+BE18 -> 1 | CN18: =+BE18 -> 1 | CO18: =+BI18 -> 1 | CP18: =+BI18 -> 1 | CQ18: =+BI18 -> 1 | CR18: =+BI18 -> 1 | CS18: =+BM18 -> 1 | CT18: =+BM18 -> 1 | CU18: =+BM18 -> 1 | CV18: =+BM18 -> 1 | CW18: =+BQ18 -> 1 | CX18: =+BQ18 -> 1 | CY18: =+BQ18 -> 1 | CZ18: =+BQ18 -> 1 | DA18: =+BU18 -> 1 | DB18: =+BU18 -> 1 | DC18: =+BU18 -> 1 | DD18: =+BU18 -> 1 | DE18: =+BY18 -> 1 | DF18: =+BY18 -> 1 | DG18: =+BY18 -> 1 | DH18: =+BY18 -> 1 | DI18: =+CC18 -> 1 | DJ18: =+CC18 -> 1 | DK18: =+CC18 -> 1 | DL18: =+CC18 -> 1 | DM18: =+CG18 -> 1 | DN18: =+CG18 -> 1 | DO18: =+CG18 -> 1 | DP18: =+CG18 -> 1 | DQ18: =+CK18 -> 1 | DR18: =+CK18 -> 1 | DS18: =+CK18 -> 1 | DT18: =+CK18 -> 1 | DU18: =+CO18 -> 1 | DV18: =+CO18 -> 1 | DW18: =+CO18 -> 1 | DX18: =+CO18 -> 1 | DY18: =+CS18 -> 1 | DZ18: =+CS18 -> 1 | EA18: =+CS18 -> 1 | EB18: =+CS18 -> 1 | EC18: =+CW18 -> 1 | ED18: =+CW18 -> 1 | EE18: =+CW18 -> 1 | EF18: =+CW18 -> 1 | EG18: =+DA18 -> 1 | EH18: =+DA18 -> 1 | EI18: =+DA18 -> 1 | EJ18: =+DA18 -> 1 | EK18: =+DE18 -> 1 | EL18: =+DE18 -> 1 | EM18: =+DE18 -> 1 | EN18: =+DE18 -> 1 | EO18: =+DI18 -> 1 | EP18: =+DI18 -> 1 | EQ18: =+DI18 -> 1 | ER18: =+DI18 -> 1 | ES18: =+DM18 -> 1 | ET18: =+DM18 -> 1 | EU18: =+DM18 -> 1 | EV18: =+DM18 -> 1 | EW18: =SUM(I18:EV18)/4 -> 30 | EX18: 16 | EY18: =24-EX18 -> 8 | EZ18: =+EW18*EX18*28 -> 13440 | FA18: =+EW18*EY18*30 -> 7200
C19: Midia 8 | D19: Adet | E19: 1 | AG19: =+E19 -> 1 | AH19: =+E19 -> 1 | AI19: =+E19 -> 1 | AJ19: =+E19 -> 1 | AK19: =+E19 -> 1 | AL19: =+E19 -> 1 | AM19: =+E19 -> 1 | AN19: =+E19 -> 1 | AO19: =+E19 -> 1 | AP19: =+E19 -> 1 | AQ19: =+E19 -> 1 | AR19: =+E19 -> 1 | AS19: =+E19 -> 1 | AT19: =+E19 -> 1 | AU19: =+E19 -> 1 | AV19: =+E19 -> 1 | AW19: =+E19 -> 1 | AX19: =+E19 -> 1 | AY19: =+E19 -> 1 | AZ19: =+E19 -> 1 | BA19: =+E19 -> 1 | BB19: =+E19 -> 1 | BC19: =+E19 -> 1 | BD19: =+E19 -> 1 | BE19: =+E19 -> 1 | BF19: =+E19 -> 1 | BG19: =+E19 -> 1 | BH19: =+E19 -> 1 | BI19: =+E19 -> 1 | BJ19: =+E19 -> 1 | BK19: =+E19 -> 1 | BL19: =+E19 -> 1 | BM19: =+E19 -> 1 | BN19: =+E19 -> 1 | BO19: =+E19 -> 1 | BP19: =+E19 -> 1 | BQ19: =+AK19 -> 1 | BR19: =+AK19 -> 1 | BS19: =+AK19 -> 1 | BT19: =+AK19 -> 1 | BU19: =+AO19 -> 1 | BV19: =+AO19 -> 1 | BW19: =+AO19 -> 1 | BX19: =+AO19 -> 1 | BY19: =+AS19 -> 1 | BZ19: =+AS19 -> 1 | CA19: =+AS19 -> 1 | CB19: =+AS19 -> 1 | CC19: =+AW19 -> 1 | CD19: =+AW19 -> 1 | CE19: =+AW19 -> 1 | CF19: =+AW19 -> 1 | CG19: =+BA19 -> 1 | CH19: =+BA19 -> 1 | CI19: =+BA19 -> 1 | CJ19: =+BA19 -> 1 | CK19: =+BE19 -> 1 | CL19: =+BE19 -> 1 | CM19: =+BE19 -> 1 | CN19: =+BE19 -> 1 | CO19: =+BI19 -> 1 | CP19: =+BI19 -> 1 | CQ19: =+BI19 -> 1 | CR19: =+BI19 -> 1 | CS19: =+BM19 -> 1 | CT19: =+BM19 -> 1 | CU19: =+BM19 -> 1 | CV19: =+BM19 -> 1 | CW19: =+BQ19 -> 1 | CX19: =+BQ19 -> 1 | CY19: =+BQ19 -> 1 | CZ19: =+BQ19 -> 1 | DA19: =+BU19 -> 1 | DB19: =+BU19 -> 1 | DC19: =+BU19 -> 1 | DD19: =+BU19 -> 1 | DE19: =+BY19 -> 1 | DF19: =+BY19 -> 1 | DG19: =+BY19 -> 1 | DH19: =+BY19 -> 1 | DI19: =+CC19 -> 1 | DJ19: =+CC19 -> 1 | DK19: =+CC19 -> 1 | DL19: =+CC19 -> 1 | DM19: =+CG19 -> 1 | DN19: =+CG19 -> 1 | DO19: =+CG19 -> 1 | DP19: =+CG19 -> 1 | DQ19: =+CK19 -> 1 | DR19: =+CK19 -> 1 | DS19: =+CK19 -> 1 | DT19: =+CK19 -> 1 | DU19: =+CO19 -> 1 | DV19: =+CO19 -> 1 | DW19: =+CO19 -> 1 | DX19: =+CO19 -> 1 | DY19: =+CS19 -> 1 | DZ19: =+CS19 -> 1 | EA19: =+CS19 -> 1 | EB19: =+CS19 -> 1 | EC19: =+CW19 -> 1 | ED19: =+CW19 -> 1 | EE19: =+CW19 -> 1 | EF19: =+CW19 -> 1 | EG19: =+DA19 -> 1 | EH19: =+DA19 -> 1 | EI19: =+DA19 -> 1 | EJ19: =+DA19 -> 1 | EK19: =+DE19 -> 1 | EL19: =+DE19 -> 1 | EM19: =+DE19 -> 1 | EN19: =+DE19 -> 1 | EO19: =+DI19 -> 1 | EP19: =+DI19 -> 1 | EQ19: =+DI19 -> 1 | ER19: =+DI19 -> 1 | ES19: =+DM19 -> 1 | ET19: =+DM19 -> 1 | EU19: =+DM19 -> 1 | EV19: =+DM19 -> 1 | EW19: =SUM(I19:EV19)/4 -> 30 | EX19: 16 | EY19: =24-EX19 -> 8 | EZ19: =+EW19*EX19*28 -> 13440 | FA19: =+EW19*EY19*30 -> 7200
C20: Midia 13 | D20: Adet | E20: 1 | AG20: =+E20 -> 1 | AH20: =+E20 -> 1 | AI20: =+E20 -> 1 | AJ20: =+E20 -> 1 | AK20: =+E20 -> 1 | AL20: =+E20 -> 1 | AM20: =+E20 -> 1 | AN20: =+E20 -> 1 | AO20: =+E20 -> 1 | AP20: =+E20 -> 1 | AQ20: =+E20 -> 1 | AR20: =+E20 -> 1 | AS20: =+E20 -> 1 | AT20: =+E20 -> 1 | AU20: =+E20 -> 1 | AV20: =+E20 -> 1 | AW20: =+E20 -> 1 | AX20: =+E20 -> 1 | AY20: =+E20 -> 1 | AZ20: =+E20 -> 1 | BA20: =+E20 -> 1 | BB20: =+E20 -> 1 | BC20: =+E20 -> 1 | BD20: =+E20 -> 1 | BE20: =+E20 -> 1 | BF20: =+E20 -> 1 | BG20: =+E20 -> 1 | BH20: =+E20 -> 1 | BI20: =+E20 -> 1 | BJ20: =+E20 -> 1 | BK20: =+E20 -> 1 | BL20: =+E20 -> 1 | BM20: =+E20 -> 1 | BN20: =+E20 -> 1 | BO20: =+E20 -> 1 | BP20: =+E20 -> 1 | BQ20: =+AK20 -> 1 | BR20: =+AK20 -> 1 | BS20: =+AK20 -> 1 | BT20: =+AK20 -> 1 | BU20: =+AO20 -> 1 | BV20: =+AO20 -> 1 | BW20: =+AO20 -> 1 | BX20: =+AO20 -> 1 | BY20: =+AS20 -> 1 | BZ20: =+AS20 -> 1 | CA20: =+AS20 -> 1 | CB20: =+AS20 -> 1 | CC20: =+AW20 -> 1 | CD20: =+AW20 -> 1 | CE20: =+AW20 -> 1 | CF20: =+AW20 -> 1 | CG20: =+BA20 -> 1 | CH20: =+BA20 -> 1 | CI20: =+BA20 -> 1 | CJ20: =+BA20 -> 1 | CK20: =+BE20 -> 1 | CL20: =+BE20 -> 1 | CM20: =+BE20 -> 1 | CN20: =+BE20 -> 1 | CO20: =+BI20 -> 1 | CP20: =+BI20 -> 1 | CQ20: =+BI20 -> 1 | CR20: =+BI20 -> 1 | CS20: =+BM20 -> 1 | CT20: =+BM20 -> 1 | CU20: =+BM20 -> 1 | CV20: =+BM20 -> 1 | CW20: =+BQ20 -> 1 | CX20: =+BQ20 -> 1 | CY20: =+BQ20 -> 1 | CZ20: =+BQ20 -> 1 | DA20: =+BU20 -> 1 | DB20: =+BU20 -> 1 | DC20: =+BU20 -> 1 | DD20: =+BU20 -> 1 | DE20: =+BY20 -> 1 | DF20: =+BY20 -> 1 | DG20: =+BY20 -> 1 | DH20: =+BY20 -> 1 | DI20: =+CC20 -> 1 | DJ20: =+CC20 -> 1 | DK20: =+CC20 -> 1 | DL20: =+CC20 -> 1 | DM20: =+CG20 -> 1 | DN20: =+CG20 -> 1 | DO20: =+CG20 -> 1 | DP20: =+CG20 -> 1 | DQ20: =+CK20 -> 1 | DR20: =+CK20 -> 1 | DS20: =+CK20 -> 1 | DT20: =+CK20 -> 1 | DU20: =+CO20 -> 1 | DV20: =+CO20 -> 1 | DW20: =+CO20 -> 1 | DX20: =+CO20 -> 1 | DY20: =+CS20 -> 1 | DZ20: =+CS20 -> 1 | EA20: =+CS20 -> 1 | EB20: =+CS20 -> 1 | EC20: =+CW20 -> 1 | ED20: =+CW20 -> 1 | EE20: =+CW20 -> 1 | EF20: =+CW20 -> 1 | EG20: =+DA20 -> 1 | EH20: =+DA20 -> 1 | EI20: =+DA20 -> 1 | EJ20: =+DA20 -> 1 | EK20: =+DE20 -> 1 | EL20: =+DE20 -> 1 | EM20: =+DE20 -> 1 | EN20: =+DE20 -> 1 | EO20: =+DI20 -> 1 | EP20: =+DI20 -> 1 | EQ20: =+DI20 -> 1 | ER20: =+DI20 -> 1 | ES20: =+DM20 -> 1 | ET20: =+DM20 -> 1 | EU20: =+DM20 -> 1 | EV20: =+DM20 -> 1 | EW20: =SUM(I20:EV20)/4 -> 30 | EX20: 16 | EY20: =24-EX20 -> 8 | EZ20: =+EW20*EX20*28 -> 13440 | FA20: =+EW20*EY20*30 -> 7200
C21: Paşa | D21: Adet | E21: 1 | AG21: =+E21 -> 1 | AH21: =+E21 -> 1 | AI21: =+E21 -> 1 | AJ21: =+E21 -> 1 | AK21: =+E21 -> 1 | AL21: =+E21 -> 1 | AM21: =+E21 -> 1 | AN21: =+E21 -> 1 | AO21: =+E21 -> 1 | AP21: =+E21 -> 1 | AQ21: =+E21 -> 1 | AR21: =+E21 -> 1 | AS21: =+E21 -> 1 | AT21: =+E21 -> 1 | AU21: =+E21 -> 1 | AV21: =+E21 -> 1 | AW21: =+E21 -> 1 | AX21: =+E21 -> 1 | AY21: =+E21 -> 1 | AZ21: =+E21 -> 1 | BA21: =+E21 -> 1 | BB21: =+E21 -> 1 | BC21: =+E21 -> 1 | BD21: =+E21 -> 1 | BE21: =+E21 -> 1 | BF21: =+E21 -> 1 | BG21: =+E21 -> 1 | BH21: =+E21 -> 1 | BI21: =+E21 -> 1 | BJ21: =+E21 -> 1 | BK21: =+E21 -> 1 | BL21: =+E21 -> 1 | BM21: =+E21 -> 1 | BN21: =+E21 -> 1 | BO21: =+E21 -> 1 | BP21: =+E21 -> 1 | BQ21: =+AK21 -> 1 | BR21: =+AK21 -> 1 | BS21: =+AK21 -> 1 | BT21: =+AK21 -> 1 | BU21: =+AO21 -> 1 | BV21: =+AO21 -> 1 | BW21: =+AO21 -> 1 | BX21: =+AO21 -> 1 | BY21: =+AS21 -> 1 | BZ21: =+AS21 -> 1 | CA21: =+AS21 -> 1 | CB21: =+AS21 -> 1 | CC21: =+AW21 -> 1 | CD21: =+AW21 -> 1 | CE21: =+AW21 -> 1 | CF21: =+AW21 -> 1 | CG21: =+BA21 -> 1 | CH21: =+BA21 -> 1 | CI21: =+BA21 -> 1 | CJ21: =+BA21 -> 1 | CK21: =+BE21 -> 1 | CL21: =+BE21 -> 1 | CM21: =+BE21 -> 1 | CN21: =+BE21 -> 1 | CO21: =+BI21 -> 1 | CP21: =+BI21 -> 1 | CQ21: =+BI21 -> 1 | CR21: =+BI21 -> 1 | CS21: =+BM21 -> 1 | CT21: =+BM21 -> 1 | CU21: =+BM21 -> 1 | CV21: =+BM21 -> 1 | CW21: =+BQ21 -> 1 | CX21: =+BQ21 -> 1 | CY21: =+BQ21 -> 1 | CZ21: =+BQ21 -> 1 | DA21: =+BU21 -> 1 | DB21: =+BU21 -> 1 | DC21: =+BU21 -> 1 | DD21: =+BU21 -> 1 | DE21: =+BY21 -> 1 | DF21: =+BY21 -> 1 | DG21: =+BY21 -> 1 | DH21: =+BY21 -> 1 | DI21: =+CC21 -> 1 | DJ21: =+CC21 -> 1 | DK21: =+CC21 -> 1 | DL21: =+CC21 -> 1 | DM21: =+CG21 -> 1 | DN21: =+CG21 -> 1 | DO21: =+CG21 -> 1 | DP21: =+CG21 -> 1 | DQ21: =+CK21 -> 1 | DR21: =+CK21 -> 1 | DS21: =+CK21 -> 1 | DT21: =+CK21 -> 1 | DU21: =+CO21 -> 1 | DV21: =+CO21 -> 1 | DW21: =+CO21 -> 1 | DX21: =+CO21 -> 1 | DY21: =+CS21 -> 1 | DZ21: =+CS21 -> 1 | EA21: =+CS21 -> 1 | EB21: =+CS21 -> 1 | EC21: =+CW21 -> 1 | ED21: =+CW21 -> 1 | EE21: =+CW21 -> 1 | EF21: =+CW21 -> 1 | EG21: =+DA21 -> 1 | EH21: =+DA21 -> 1 | EI21: =+DA21 -> 1 | EJ21: =+DA21 -> 1 | EK21: =+DE21 -> 1 | EL21: =+DE21 -> 1 | EM21: =+DE21 -> 1 | EN21: =+DE21 -> 1 | EO21: =+DI21 -> 1 | EP21: =+DI21 -> 1 | EQ21: =+DI21 -> 1 | ER21: =+DI21 -> 1 | ES21: =+DM21 -> 1 | ET21: =+DM21 -> 1 | EU21: =+DM21 -> 1 | EV21: =+DM21 -> 1 | EW21: =SUM(I21:EV21)/4 -> 30 | EX21: 16 | EY21: =24-EX21 -> 8 | EZ21: =+EW21*EX21*28 -> 13440 | FA21: =+EW21*EY21*30 -> 7200
C22: Hila | D22: Adet | E22: 1 | AG22: =+E22 -> 1 | AH22: =+E22 -> 1 | AI22: =+E22 -> 1 | AJ22: =+E22 -> 1 | AK22: =+E22 -> 1 | AL22: =+E22 -> 1 | AM22: =+E22 -> 1 | AN22: =+E22 -> 1 | AO22: =+E22 -> 1 | AP22: =+E22 -> 1 | AQ22: =+E22 -> 1 | AR22: =+E22 -> 1 | AS22: =+E22 -> 1 | AT22: =+E22 -> 1 | AU22: =+E22 -> 1 | AV22: =+E22 -> 1 | AW22: =+E22 -> 1 | AX22: =+E22 -> 1 | AY22: =+E22 -> 1 | AZ22: =+E22 -> 1 | BA22: =+E22 -> 1 | BB22: =+E22 -> 1 | BC22: =+E22 -> 1 | BD22: =+E22 -> 1 | BE22: =+E22 -> 1 | BF22: =+E22 -> 1 | BG22: =+E22 -> 1 | BH22: =+E22 -> 1 | BI22: =+E22 -> 1 | BJ22: =+E22 -> 1 | BK22: =+E22 -> 1 | BL22: =+E22 -> 1 | BM22: =+E22 -> 1 | BN22: =+E22 -> 1 | BO22: =+E22 -> 1 | BP22: =+E22 -> 1 | BQ22: =+AK22 -> 1 | BR22: =+AK22 -> 1 | BS22: =+AK22 -> 1 | BT22: =+AK22 -> 1 | BU22: =+AO22 -> 1 | BV22: =+AO22 -> 1 | BW22: =+AO22 -> 1 | BX22: =+AO22 -> 1 | BY22: =+AS22 -> 1 | BZ22: =+AS22 -> 1 | CA22: =+AS22 -> 1 | CB22: =+AS22 -> 1 | CC22: =+AW22 -> 1 | CD22: =+AW22 -> 1 | CE22: =+AW22 -> 1 | CF22: =+AW22 -> 1 | CG22: =+BA22 -> 1 | CH22: =+BA22 -> 1 | CI22: =+BA22 -> 1 | CJ22: =+BA22 -> 1 | CK22: =+BE22 -> 1 | CL22: =+BE22 -> 1 | CM22: =+BE22 -> 1 | CN22: =+BE22 -> 1 | CO22: =+BI22 -> 1 | CP22: =+BI22 -> 1 | CQ22: =+BI22 -> 1 | CR22: =+BI22 -> 1 | CS22: =+BM22 -> 1 | CT22: =+BM22 -> 1 | CU22: =+BM22 -> 1 | CV22: =+BM22 -> 1 | CW22: =+BQ22 -> 1 | CX22: =+BQ22 -> 1 | CY22: =+BQ22 -> 1 | CZ22: =+BQ22 -> 1 | DA22: =+BU22 -> 1 | DB22: =+BU22 -> 1 | DC22: =+BU22 -> 1 | DD22: =+BU22 -> 1 | DE22: =+BY22 -> 1 | DF22: =+BY22 -> 1 | DG22: =+BY22 -> 1 | DH22: =+BY22 -> 1 | DI22: =+CC22 -> 1 | DJ22: =+CC22 -> 1 | DK22: =+CC22 -> 1 | DL22: =+CC22 -> 1 | DM22: =+CG22 -> 1 | DN22: =+CG22 -> 1 | DO22: =+CG22 -> 1 | DP22: =+CG22 -> 1 | DQ22: =+CK22 -> 1 | DR22: =+CK22 -> 1 | DS22: =+CK22 -> 1 | DT22: =+CK22 -> 1 | DU22: =+CO22 -> 1 | DV22: =+CO22 -> 1 | DW22: =+CO22 -> 1 | DX22: =+CO22 -> 1 | DY22: =+CS22 -> 1 | DZ22: =+CS22 -> 1 | EA22: =+CS22 -> 1 | EB22: =+CS22 -> 1 | EC22: =+CW22 -> 1 | ED22: =+CW22 -> 1 | EE22: =+CW22 -> 1 | EF22: =+CW22 -> 1 | EG22: =+DA22 -> 1 | EH22: =+DA22 -> 1 | EI22: =+DA22 -> 1 | EJ22: =+DA22 -> 1 | EK22: =+DE22 -> 1 | EL22: =+DE22 -> 1 | EM22: =+DE22 -> 1 | EN22: =+DE22 -> 1 | EO22: =+DI22 -> 1 | EP22: =+DI22 -> 1 | EQ22: =+DI22 -> 1 | ER22: =+DI22 -> 1 | ES22: =+DM22 -> 1 | ET22: =+DM22 -> 1 | EU22: =+DM22 -> 1 | EV22: =+DM22 -> 1 | EW22: =SUM(I22:EV22)/4 -> 30 | EX22: 16 | EY22: =24-EX22 -> 8 | EZ22: =+EW22*EX22*28 -> 13440 | FA22: =+EW22*EY22*30 -> 7200
C23: Daria | D23: Adet | E23: 1 | AG23: =+E23 -> 1 | AH23: =+E23 -> 1 | AI23: =+E23 -> 1 | AJ23: =+E23 -> 1 | AK23: =+E23 -> 1 | AL23: =+E23 -> 1 | AM23: =+E23 -> 1 | AN23: =+E23 -> 1 | AO23: =+E23 -> 1 | AP23: =+E23 -> 1 | AQ23: =+E23 -> 1 | AR23: =+E23 -> 1 | AS23: =+E23 -> 1 | AT23: =+E23 -> 1 | AU23: =+E23 -> 1 | AV23: =+E23 -> 1 | AW23: =+E23 -> 1 | AX23: =+E23 -> 1 | AY23: =+E23 -> 1 | AZ23: =+E23 -> 1 | BA23: =+E23 -> 1 | BB23: =+E23 -> 1 | BC23: =+E23 -> 1 | BD23: =+E23 -> 1 | BE23: =+E23 -> 1 | BF23: =+E23 -> 1 | BG23: =+E23 -> 1 | BH23: =+E23 -> 1 | BI23: =+E23 -> 1 | BJ23: =+E23 -> 1 | BK23: =+E23 -> 1 | BL23: =+E23 -> 1 | BM23: =+E23 -> 1 | BN23: =+E23 -> 1 | BO23: =+E23 -> 1 | BP23: =+E23 -> 1 | BQ23: =+AK23 -> 1 | BR23: =+AK23 -> 1 | BS23: =+AK23 -> 1 | BT23: =+AK23 -> 1 | BU23: =+AO23 -> 1 | BV23: =+AO23 -> 1 | BW23: =+AO23 -> 1 | BX23: =+AO23 -> 1 | BY23: =+AS23 -> 1 | BZ23: =+AS23 -> 1 | CA23: =+AS23 -> 1 | CB23: =+AS23 -> 1 | CC23: =+AW23 -> 1 | CD23: =+AW23 -> 1 | CE23: =+AW23 -> 1 | CF23: =+AW23 -> 1 | CG23: =+BA23 -> 1 | CH23: =+BA23 -> 1 | CI23: =+BA23 -> 1 | CJ23: =+BA23 -> 1 | CK23: =+BE23 -> 1 | CL23: =+BE23 -> 1 | CM23: =+BE23 -> 1 | CN23: =+BE23 -> 1 | CO23: =+BI23 -> 1 | CP23: =+BI23 -> 1 | CQ23: =+BI23 -> 1 | CR23: =+BI23 -> 1 | CS23: =+BM23 -> 1 | CT23: =+BM23 -> 1 | CU23: =+BM23 -> 1 | CV23: =+BM23 -> 1 | CW23: =+BQ23 -> 1 | CX23: =+BQ23 -> 1 | CY23: =+BQ23 -> 1 | CZ23: =+BQ23 -> 1 | DA23: =+BU23 -> 1 | DB23: =+BU23 -> 1 | DC23: =+BU23 -> 1 | DD23: =+BU23 -> 1 | DE23: =+BY23 -> 1 | DF23: =+BY23 -> 1 | DG23: =+BY23 -> 1 | DH23: =+BY23 -> 1 | DI23: =+CC23 -> 1 | DJ23: =+CC23 -> 1 | DK23: =+CC23 -> 1 | DL23: =+CC23 -> 1 | DM23: =+CG23 -> 1 | DN23: =+CG23 -> 1 | DO23: =+CG23 -> 1 | DP23: =+CG23 -> 1 | DQ23: =+CK23 -> 1 | DR23: =+CK23 -> 1 | DS23: =+CK23 -> 1 | DT23: =+CK23 -> 1 | DU23: =+CO23 -> 1 | DV23: =+CO23 -> 1 | DW23: =+CO23 -> 1 | DX23: =+CO23 -> 1 | DY23: =+CS23 -> 1 | DZ23: =+CS23 -> 1 | EA23: =+CS23 -> 1 | EB23: =+CS23 -> 1 | EC23: =+CW23 -> 1 | ED23: =+CW23 -> 1 | EE23: =+CW23 -> 1 | EF23: =+CW23 -> 1 | EG23: =+DA23 -> 1 | EH23: =+DA23 -> 1 | EI23: =+DA23 -> 1 | EJ23: =+DA23 -> 1 | EK23: =+DE23 -> 1 | EL23: =+DE23 -> 1 | EM23: =+DE23 -> 1 | EN23: =+DE23 -> 1 | EO23: =+DI23 -> 1 | EP23: =+DI23 -> 1 | EQ23: =+DI23 -> 1 | ER23: =+DI23 -> 1 | ES23: =+DM23 -> 1 | ET23: =+DM23 -> 1 | EU23: =+DM23 -> 1 | EV23: =+DM23 -> 1 | EW23: =SUM(I23:EV23)/4 -> 30 | EX23: 16 | EY23: =24-EX23 -> 8 | EZ23: =+EW23*EX23*28 -> 13440 | FA23: =+EW23*EY23*30 -> 7200
C24: Hadar | D24: Adet | E24: 1 | AG24: =+E24 -> 1 | AH24: =+E24 -> 1 | AI24: =+E24 -> 1 | AJ24: =+E24 -> 1 | AK24: =+E24 -> 1 | AL24: =+E24 -> 1 | AM24: =+E24 -> 1 | AN24: =+E24 -> 1 | AO24: =+E24 -> 1 | AP24: =+E24 -> 1 | AQ24: =+E24 -> 1 | AR24: =+E24 -> 1 | AS24: =+E24 -> 1 | AT24: =+E24 -> 1 | AU24: =+E24 -> 1 | AV24: =+E24 -> 1 | AW24: =+E24 -> 1 | AX24: =+E24 -> 1 | AY24: =+E24 -> 1 | AZ24: =+E24 -> 1 | BA24: =+E24 -> 1 | BB24: =+E24 -> 1 | BC24: =+E24 -> 1 | BD24: =+E24 -> 1 | BE24: =+E24 -> 1 | BF24: =+E24 -> 1 | BG24: =+E24 -> 1 | BH24: =+E24 -> 1 | BI24: =+E24 -> 1 | BJ24: =+E24 -> 1 | BK24: =+E24 -> 1 | BL24: =+E24 -> 1 | BM24: =+E24 -> 1 | BN24: =+E24 -> 1 | BO24: =+E24 -> 1 | BP24: =+E24 -> 1 | BQ24: =+AK24 -> 1 | BR24: =+AK24 -> 1 | BS24: =+AK24 -> 1 | BT24: =+AK24 -> 1 | BU24: =+AO24 -> 1 | BV24: =+AO24 -> 1 | BW24: =+AO24 -> 1 | BX24: =+AO24 -> 1 | BY24: =+AS24 -> 1 | BZ24: =+AS24 -> 1 | CA24: =+AS24 -> 1 | CB24: =+AS24 -> 1 | CC24: =+AW24 -> 1 | CD24: =+AW24 -> 1 | CE24: =+AW24 -> 1 | CF24: =+AW24 -> 1 | CG24: =+BA24 -> 1 | CH24: =+BA24 -> 1 | CI24: =+BA24 -> 1 | CJ24: =+BA24 -> 1 | CK24: =+BE24 -> 1 | CL24: =+BE24 -> 1 | CM24: =+BE24 -> 1 | CN24: =+BE24 -> 1 | CO24: =+BI24 -> 1 | CP24: =+BI24 -> 1 | CQ24: =+BI24 -> 1 | CR24: =+BI24 -> 1 | CS24: =+BM24 -> 1 | CT24: =+BM24 -> 1 | CU24: =+BM24 -> 1 | CV24: =+BM24 -> 1 | CW24: =+BQ24 -> 1 | CX24: =+BQ24 -> 1 | CY24: =+BQ24 -> 1 | CZ24: =+BQ24 -> 1 | DA24: =+BU24 -> 1 | DB24: =+BU24 -> 1 | DC24: =+BU24 -> 1 | DD24: =+BU24 -> 1 | DE24: =+BY24 -> 1 | DF24: =+BY24 -> 1 | DG24: =+BY24 -> 1 | DH24: =+BY24 -> 1 | DI24: =+CC24 -> 1 | DJ24: =+CC24 -> 1 | DK24: =+CC24 -> 1 | DL24: =+CC24 -> 1 | DM24: =+CG24 -> 1 | DN24: =+CG24 -> 1 | DO24: =+CG24 -> 1 | DP24: =+CG24 -> 1 | DQ24: =+CK24 -> 1 | DR24: =+CK24 -> 1 | DS24: =+CK24 -> 1 | DT24: =+CK24 -> 1 | DU24: =+CO24 -> 1 | DV24: =+CO24 -> 1 | DW24: =+CO24 -> 1 | DX24: =+CO24 -> 1 | DY24: =+CS24 -> 1 | DZ24: =+CS24 -> 1 | EA24: =+CS24 -> 1 | EB24: =+CS24 -> 1 | EC24: =+CW24 -> 1 | ED24: =+CW24 -> 1 | EE24: =+CW24 -> 1 | EF24: =+CW24 -> 1 | EG24: =+DA24 -> 1 | EH24: =+DA24 -> 1 | EI24: =+DA24 -> 1 | EJ24: =+DA24 -> 1 | EK24: =+DE24 -> 1 | EL24: =+DE24 -> 1 | EM24: =+DE24 -> 1 | EN24: =+DE24 -> 1 | EO24: =+DI24 -> 1 | EP24: =+DI24 -> 1 | EQ24: =+DI24 -> 1 | ER24: =+DI24 -> 1 | ES24: =+DM24 -> 1 | ET24: =+DM24 -> 1 | EU24: =+DM24 -> 1 | EV24: =+DM24 -> 1 | EW24: =SUM(I24:EV24)/4 -> 30 | EX24: 16 | EY24: =24-EX24 -> 8 | EZ24: =+EW24*EX24*28 -> 13440 | FA24: =+EW24*EY24*30 -> 7200
C25: Split Barge (x5) | D25: Adet | E25: 5 | AG25: =+E25 -> 5 | AH25: =+E25 -> 5 | AI25: =+E25 -> 5 | AJ25: =+E25 -> 5 | AK25: =+E25 -> 5 | AL25: =+E25 -> 5 | AM25: =+E25 -> 5 | AN25: =+E25 -> 5 | AO25: =+E25 -> 5 | AP25: =+E25 -> 5 | AQ25: =+E25 -> 5 | AR25: =+E25 -> 5 | AS25: =+E25 -> 5 | AT25: =+E25 -> 5 | AU25: =+E25 -> 5 | AV25: =+E25 -> 5 | AW25: =+E25 -> 5 | AX25: =+E25 -> 5 | AY25: =+E25 -> 5 | AZ25: =+E25 -> 5 | BA25: =+E25 -> 5 | BB25: =+E25 -> 5 | BC25: =+E25 -> 5 | BD25: =+E25 -> 5 | BE25: =+E25 -> 5 | BF25: =+E25 -> 5 | BG25: =+E25 -> 5 | BH25: =+E25 -> 5 | BI25: =+E25 -> 5 | BJ25: =+E25 -> 5 | BK25: =+E25 -> 5 | BL25: =+E25 -> 5 | BM25: =+E25 -> 5 | BN25: =+E25 -> 5 | BO25: =+E25 -> 5 | BP25: =+E25 -> 5 | BQ25: =+AK25 -> 5 | BR25: =+AK25 -> 5 | BS25: =+AK25 -> 5 | BT25: =+AK25 -> 5 | BU25: =+AO25 -> 5 | BV25: =+AO25 -> 5 | BW25: =+AO25 -> 5 | BX25: =+AO25 -> 5 | BY25: =+AS25 -> 5 | BZ25: =+AS25 -> 5 | CA25: =+AS25 -> 5 | CB25: =+AS25 -> 5 | CC25: =+AW25 -> 5 | CD25: =+AW25 -> 5 | CE25: =+AW25 -> 5 | CF25: =+AW25 -> 5 | CG25: =+BA25 -> 5 | CH25: =+BA25 -> 5 | CI25: =+BA25 -> 5 | CJ25: =+BA25 -> 5 | CK25: =+BE25 -> 5 | CL25: =+BE25 -> 5 | CM25: =+BE25 -> 5 | CN25: =+BE25 -> 5 | CO25: =+BI25 -> 5 | CP25: =+BI25 -> 5 | CQ25: =+BI25 -> 5 | CR25: =+BI25 -> 5 | CS25: =+BM25 -> 5 | CT25: =+BM25 -> 5 | CU25: =+BM25 -> 5 | CV25: =+BM25 -> 5 | CW25: =+BQ25 -> 5 | CX25: =+BQ25 -> 5 | CY25: =+BQ25 -> 5 | CZ25: =+BQ25 -> 5 | DA25: =+BU25 -> 5 | DB25: =+BU25 -> 5 | DC25: =+BU25 -> 5 | DD25: =+BU25 -> 5 | DE25: =+BY25 -> 5 | DF25: =+BY25 -> 5 | DG25: =+BY25 -> 5 | DH25: =+BY25 -> 5 | DI25: =+CC25 -> 5 | DJ25: =+CC25 -> 5 | DK25: =+CC25 -> 5 | DL25: =+CC25 -> 5 | DM25: =+CG25 -> 5 | DN25: =+CG25 -> 5 | DO25: =+CG25 -> 5 | DP25: =+CG25 -> 5 | DQ25: =+CK25 -> 5 | DR25: =+CK25 -> 5 | DS25: =+CK25 -> 5 | DT25: =+CK25 -> 5 | DU25: =+CO25 -> 5 | DV25: =+CO25 -> 5 | DW25: =+CO25 -> 5 | DX25: =+CO25 -> 5 | DY25: =+CS25 -> 5 | DZ25: =+CS25 -> 5 | EA25: =+CS25 -> 5 | EB25: =+CS25 -> 5 | EC25: =+CW25 -> 5 | ED25: =+CW25 -> 5 | EE25: =+CW25 -> 5 | EF25: =+CW25 -> 5 | EG25: =+DA25 -> 5 | EH25: =+DA25 -> 5 | EI25: =+DA25 -> 5 | EJ25: =+DA25 -> 5 | EK25: =+DE25 -> 5 | EL25: =+DE25 -> 5 | EM25: =+DE25 -> 5 | EN25: =+DE25 -> 5 | EO25: =+DI25 -> 5 | EP25: =+DI25 -> 5 | EQ25: =+DI25 -> 5 | ER25: =+DI25 -> 5 | ES25: =+DM25 -> 5 | ET25: =+DM25 -> 5 | EU25: =+DM25 -> 5 | EV25: =+DM25 -> 5 | EW25: =SUM(I25:EV25)/4 -> 150 | EX25: 16 | EY25: =24-EX25 -> 8 | EZ25: =+EW25*EX25*28 -> 67200 | FA25: =+EW25*EY25*30 -> 36000
C26: Bozkurt | D26: Adet | E26: 1 | AG26: =+E26 -> 1 | AH26: =+E26 -> 1 | AI26: =+E26 -> 1 | AJ26: =+E26 -> 1 | AK26: =+E26 -> 1 | AL26: =+E26 -> 1 | AM26: =+E26 -> 1 | AN26: =+E26 -> 1 | AO26: =+E26 -> 1 | AP26: =+E26 -> 1 | AQ26: =+E26 -> 1 | AR26: =+E26 -> 1 | AS26: =+E26 -> 1 | AT26: =+E26 -> 1 | AU26: =+E26 -> 1 | AV26: =+E26 -> 1 | AW26: =+E26 -> 1 | AX26: =+E26 -> 1 | AY26: =+E26 -> 1 | AZ26: =+E26 -> 1 | BA26: =+E26 -> 1 | BB26: =+E26 -> 1 | BC26: =+E26 -> 1 | BD26: =+E26 -> 1 | BE26: =+E26 -> 1 | BF26: =+E26 -> 1 | BG26: =+E26 -> 1 | BH26: =+E26 -> 1 | BI26: =+E26 -> 1 | BJ26: =+E26 -> 1 | BK26: =+E26 -> 1 | BL26: =+E26 -> 1 | BM26: =+E26 -> 1 | BN26: =+E26 -> 1 | BO26: =+E26 -> 1 | BP26: =+E26 -> 1 | BQ26: =+AK26 -> 1 | BR26: =+AK26 -> 1 | BS26: =+AK26 -> 1 | BT26: =+AK26 -> 1 | BU26: =+AO26 -> 1 | BV26: =+AO26 -> 1 | BW26: =+AO26 -> 1 | BX26: =+AO26 -> 1 | BY26: =+AS26 -> 1 | BZ26: =+AS26 -> 1 | CA26: =+AS26 -> 1 | CB26: =+AS26 -> 1 | CC26: =+AW26 -> 1 | CD26: =+AW26 -> 1 | CE26: =+AW26 -> 1 | CF26: =+AW26 -> 1 | CG26: =+BA26 -> 1 | CH26: =+BA26 -> 1 | CI26: =+BA26 -> 1 | CJ26: =+BA26 -> 1 | CK26: =+BE26 -> 1 | CL26: =+BE26 -> 1 | CM26: =+BE26 -> 1 | CN26: =+BE26 -> 1 | CO26: =+BI26 -> 1 | CP26: =+BI26 -> 1 | CQ26: =+BI26 -> 1 | CR26: =+BI26 -> 1 | CS26: =+BM26 -> 1 | CT26: =+BM26 -> 1 | CU26: =+BM26 -> 1 | CV26: =+BM26 -> 1 | CW26: =+BQ26 -> 1 | CX26: =+BQ26 -> 1 | CY26: =+BQ26 -> 1 | CZ26: =+BQ26 -> 1 | DA26: =+BU26 -> 1 | DB26: =+BU26 -> 1 | DC26: =+BU26 -> 1 | DD26: =+BU26 -> 1 | DE26: =+BY26 -> 1 | DF26: =+BY26 -> 1 | DG26: =+BY26 -> 1 | DH26: =+BY26 -> 1 | DI26: =+CC26 -> 1 | DJ26: =+CC26 -> 1 | DK26: =+CC26 -> 1 | DL26: =+CC26 -> 1 | DM26: =+CG26 -> 1 | DN26: =+CG26 -> 1 | DO26: =+CG26 -> 1 | DP26: =+CG26 -> 1 | DQ26: =+CK26 -> 1 | DR26: =+CK26 -> 1 | DS26: =+CK26 -> 1 | DT26: =+CK26 -> 1 | DU26: =+CO26 -> 1 | DV26: =+CO26 -> 1 | DW26: =+CO26 -> 1 | DX26: =+CO26 -> 1 | DY26: =+CS26 -> 1 | DZ26: =+CS26 -> 1 | EA26: =+CS26 -> 1 | EB26: =+CS26 -> 1 | EC26: =+CW26 -> 1 | ED26: =+CW26 -> 1 | EE26: =+CW26 -> 1 | EF26: =+CW26 -> 1 | EG26: =+DA26 -> 1 | EH26: =+DA26 -> 1 | EI26: =+DA26 -> 1 | EJ26: =+DA26 -> 1 | EK26: =+DE26 -> 1 | EL26: =+DE26 -> 1 | EM26: =+DE26 -> 1 | EN26: =+DE26 -> 1 | EO26: =+DI26 -> 1 | EP26: =+DI26 -> 1 | EQ26: =+DI26 -> 1 | ER26: =+DI26 -> 1 | ES26: =+DM26 -> 1 | ET26: =+DM26 -> 1 | EU26: =+DM26 -> 1 | EV26: =+DM26 -> 1 | EW26: =SUM(I26:EV26)/4 -> 30 | EX26: 16 | EY26: =24-EX26 -> 8 | EZ26: =+EW26*EX26*28 -> 13440 | FA26: =+EW26*EY26*30 -> 7200
C27: Yozgat | D27: Adet | E27: 1 | AG27: =+E27 -> 1 | AH27: =+E27 -> 1 | AI27: =+E27 -> 1 | AJ27: =+E27 -> 1 | AK27: =+E27 -> 1 | AL27: =+E27 -> 1 | AM27: =+E27 -> 1 | AN27: =+E27 -> 1 | AO27: =+E27 -> 1 | AP27: =+E27 -> 1 | AQ27: =+E27 -> 1 | AR27: =+E27 -> 1 | AS27: =+E27 -> 1 | AT27: =+E27 -> 1 | AU27: =+E27 -> 1 | AV27: =+E27 -> 1 | AW27: =+E27 -> 1 | AX27: =+E27 -> 1 | AY27: =+E27 -> 1 | AZ27: =+E27 -> 1 | BA27: =+E27 -> 1 | BB27: =+E27 -> 1 | BC27: =+E27 -> 1 | BD27: =+E27 -> 1 | BE27: =+E27 -> 1 | BF27: =+E27 -> 1 | BG27: =+E27 -> 1 | BH27: =+E27 -> 1 | BI27: =+E27 -> 1 | BJ27: =+E27 -> 1 | BK27: =+E27 -> 1 | BL27: =+E27 -> 1 | BM27: =+E27 -> 1 | BN27: =+E27 -> 1 | BO27: =+E27 -> 1 | BP27: =+E27 -> 1 | BQ27: =+AK27 -> 1 | BR27: =+AK27 -> 1 | BS27: =+AK27 -> 1 | BT27: =+AK27 -> 1 | BU27: =+AO27 -> 1 | BV27: =+AO27 -> 1 | BW27: =+AO27 -> 1 | BX27: =+AO27 -> 1 | BY27: =+AS27 -> 1 | BZ27: =+AS27 -> 1 | CA27: =+AS27 -> 1 | CB27: =+AS27 -> 1 | CC27: =+AW27 -> 1 | CD27: =+AW27 -> 1 | CE27: =+AW27 -> 1 | CF27: =+AW27 -> 1 | CG27: =+BA27 -> 1 | CH27: =+BA27 -> 1 | CI27: =+BA27 -> 1 | CJ27: =+BA27 -> 1 | CK27: =+BE27 -> 1 | CL27: =+BE27 -> 1 | CM27: =+BE27 -> 1 | CN27: =+BE27 -> 1 | CO27: =+BI27 -> 1 | CP27: =+BI27 -> 1 | CQ27: =+BI27 -> 1 | CR27: =+BI27 -> 1 | CS27: =+BM27 -> 1 | CT27: =+BM27 -> 1 | CU27: =+BM27 -> 1 | CV27: =+BM27 -> 1 | CW27: =+BQ27 -> 1 | CX27: =+BQ27 -> 1 | CY27: =+BQ27 -> 1 | CZ27: =+BQ27 -> 1 | DA27: =+BU27 -> 1 | DB27: =+BU27 -> 1 | DC27: =+BU27 -> 1 | DD27: =+BU27 -> 1 | DE27: =+BY27 -> 1 | DF27: =+BY27 -> 1 | DG27: =+BY27 -> 1 | DH27: =+BY27 -> 1 | DI27: =+CC27 -> 1 | DJ27: =+CC27 -> 1 | DK27: =+CC27 -> 1 | DL27: =+CC27 -> 1 | DM27: =+CG27 -> 1 | DN27: =+CG27 -> 1 | DO27: =+CG27 -> 1 | DP27: =+CG27 -> 1 | DQ27: =+CK27 -> 1 | DR27: =+CK27 -> 1 | DS27: =+CK27 -> 1 | DT27: =+CK27 -> 1 | DU27: =+CO27 -> 1 | DV27: =+CO27 -> 1 | DW27: =+CO27 -> 1 | DX27: =+CO27 -> 1 | DY27: =+CS27 -> 1 | DZ27: =+CS27 -> 1 | EA27: =+CS27 -> 1 | EB27: =+CS27 -> 1 | EC27: =+CW27 -> 1 | ED27: =+CW27 -> 1 | EE27: =+CW27 -> 1 | EF27: =+CW27 -> 1 | EG27: =+DA27 -> 1 | EH27: =+DA27 -> 1 | EI27: =+DA27 -> 1 | EJ27: =+DA27 -> 1 | EK27: =+DE27 -> 1 | EL27: =+DE27 -> 1 | EM27: =+DE27 -> 1 | EN27: =+DE27 -> 1 | EO27: =+DI27 -> 1 | EP27: =+DI27 -> 1 | EQ27: =+DI27 -> 1 | ER27: =+DI27 -> 1 | ES27: =+DM27 -> 1 | ET27: =+DM27 -> 1 | EU27: =+DM27 -> 1 | EV27: =+DM27 -> 1 | EW27: =SUM(I27:EV27)/4 -> 30 | EX27: 16 | EY27: =24-EX27 -> 8 | EZ27: =+EW27*EX27*28 -> 13440 | FA27: =+EW27*EY27*30 -> 7200
C28: Dalgıç | D28: Adet | E28: 1 | AG28: =+E28 -> 1 | AH28: =+E28 -> 1 | AI28: =+E28 -> 1 | AJ28: =+E28 -> 1 | AK28: =+E28 -> 1 | AL28: =+E28 -> 1 | AM28: =+E28 -> 1 | AN28: =+E28 -> 1 | AO28: =+E28 -> 1 | AP28: =+E28 -> 1 | AQ28: =+E28 -> 1 | AR28: =+E28 -> 1 | AS28: =+E28 -> 1 | AT28: =+E28 -> 1 | AU28: =+E28 -> 1 | AV28: =+E28 -> 1 | AW28: =+E28 -> 1 | AX28: =+E28 -> 1 | AY28: =+E28 -> 1 | AZ28: =+E28 -> 1 | BA28: =+E28 -> 1 | BB28: =+E28 -> 1 | BC28: =+E28 -> 1 | BD28: =+E28 -> 1 | BE28: =+E28 -> 1 | BF28: =+E28 -> 1 | BG28: =+E28 -> 1 | BH28: =+E28 -> 1 | BI28: =+E28 -> 1 | BJ28: =+E28 -> 1 | BK28: =+E28 -> 1 | BL28: =+E28 -> 1 | BM28: =+E28 -> 1 | BN28: =+E28 -> 1 | BO28: =+E28 -> 1 | BP28: =+E28 -> 1 | BQ28: =+AK28 -> 1 | BR28: =+AK28 -> 1 | BS28: =+AK28 -> 1 | BT28: =+AK28 -> 1 | BU28: =+AO28 -> 1 | BV28: =+AO28 -> 1 | BW28: =+AO28 -> 1 | BX28: =+AO28 -> 1 | BY28: =+AS28 -> 1 | BZ28: =+AS28 -> 1 | CA28: =+AS28 -> 1 | CB28: =+AS28 -> 1 | CC28: =+AW28 -> 1 | CD28: =+AW28 -> 1 | CE28: =+AW28 -> 1 | CF28: =+AW28 -> 1 | CG28: =+BA28 -> 1 | CH28: =+BA28 -> 1 | CI28: =+BA28 -> 1 | CJ28: =+BA28 -> 1 | CK28: =+BE28 -> 1 | CL28: =+BE28 -> 1 | CM28: =+BE28 -> 1 | CN28: =+BE28 -> 1 | CO28: =+BI28 -> 1 | CP28: =+BI28 -> 1 | CQ28: =+BI28 -> 1 | CR28: =+BI28 -> 1 | CS28: =+BM28 -> 1 | CT28: =+BM28 -> 1 | CU28: =+BM28 -> 1 | CV28: =+BM28 -> 1 | CW28: =+BQ28 -> 1 | CX28: =+BQ28 -> 1 | CY28: =+BQ28 -> 1 | CZ28: =+BQ28 -> 1 | DA28: =+BU28 -> 1 | DB28: =+BU28 -> 1 | DC28: =+BU28 -> 1 | DD28: =+BU28 -> 1 | DE28: =+BY28 -> 1 | DF28: =+BY28 -> 1 | DG28: =+BY28 -> 1 | DH28: =+BY28 -> 1 | DI28: =+CC28 -> 1 | DJ28: =+CC28 -> 1 | DK28: =+CC28 -> 1 | DL28: =+CC28 -> 1 | DM28: =+CG28 -> 1 | DN28: =+CG28 -> 1 | DO28: =+CG28 -> 1 | DP28: =+CG28 -> 1 | DQ28: =+CK28 -> 1 | DR28: =+CK28 -> 1 | DS28: =+CK28 -> 1 | DT28: =+CK28 -> 1 | DU28: =+CO28 -> 1 | DV28: =+CO28 -> 1 | DW28: =+CO28 -> 1 | DX28: =+CO28 -> 1 | DY28: =+CS28 -> 1 | DZ28: =+CS28 -> 1 | EA28: =+CS28 -> 1 | EB28: =+CS28 -> 1 | EC28: =+CW28 -> 1 | ED28: =+CW28 -> 1 | EE28: =+CW28 -> 1 | EF28: =+CW28 -> 1 | EG28: =+DA28 -> 1 | EH28: =+DA28 -> 1 | EI28: =+DA28 -> 1 | EJ28: =+DA28 -> 1 | EK28: =+DE28 -> 1 | EL28: =+DE28 -> 1 | EM28: =+DE28 -> 1 | EN28: =+DE28 -> 1 | EO28: =+DI28 -> 1 | EP28: =+DI28 -> 1 | EQ28: =+DI28 -> 1 | ER28: =+DI28 -> 1 | ES28: =+DM28 -> 1 | ET28: =+DM28 -> 1 | EU28: =+DM28 -> 1 | EV28: =+DM28 -> 1 | EW28: =SUM(I28:EV28)/4 -> 30 | EX28: 16 | EY28: =24-EX28 -> 8 | EZ28: =+EW28*EX28*28 -> 13440 | FA28: =+EW28*EY28*30 -> 7200
... C36: Dump Truck (x20) | D36: Adet | E36: 20 | AG36: =+E36 -> 20 | AH36: =+E36 -> 20 | AI36: =+E36 -> 20 | AJ36: =+E36 -> 20 | AK36: =+E36 -> 20 | AL36: =+E36 -> 20 | AM36: =+E36 -> 20 | AN36: =+E36 -> 20 | AO36: =+E36 -> 20 | AP36: =+E36 -> 20 | AQ36: =+E36 -> 20 | AR36: =+E36 -> 20 | AS36: =+E36 -> 20 | AT36: =+E36 -> 20 | AU36: =+E36 -> 20 | AV36: =+E36 -> 20 | AW36: =+E36 -> 20 | AX36: =+E36 -> 20 | AY36: =+E36 -> 20 | AZ36: =+E36 -> 20 | BA36: =+E36 -> 20 | BB36: =+E36 -> 20 | BC36: =+E36 -> 20 | BD36: =+E36 -> 20 | BE36: =+E36 -> 20 | BF36: =+E36 -> 20 | BG36: =+E36 -> 20 | BH36: =+E36 -> 20 | BI36: =+E36 -> 20 | BJ36: =+E36 -> 20 | BK36: =+E36 -> 20 | BL36: =+E36 -> 20 | BM36: =+E36 -> 20 | BN36: =+E36 -> 20 | BO36: =+E36 -> 20 | BP36: =+E36 -> 20 | BQ36: =+AK36 -> 20 | BR36: =+AK36 -> 20 | BS36: =+AK36 -> 20 | BT36: =+AK36 -> 20 | BU36: =+AO36 -> 20 | BV36: =+AO36 -> 20 | BW36: =+AO36 -> 20 | BX36: =+AO36 -> 20 | BY36: =+AS36 -> 20 | BZ36: =+AS36 -> 20 | CA36: =+AS36 -> 20 | CB36: =+AS36 -> 20 | CC36: =+AW36 -> 20 | CD36: =+AW36 -> 20 | CE36: =+AW36 -> 20 | CF36: =+AW36 -> 20 | CG36: =+BA36 -> 20 | CH36: =+BA36 -> 20 | CI36: =+BA36 -> 20 | CJ36: =+BA36 -> 20 | CK36: =+BE36 -> 20 | CL36: =+BE36 -> 20 | CM36: =+BE36 -> 20 | CN36: =+BE36 -> 20 | CO36: =+BI36 -> 20 | CP36: =+BI36 -> 20 | CQ36: =+BI36 -> 20 | CR36: =+BI36 -> 20 | CS36: =+BM36 -> 20 | CT36: =+BM36 -> 20 | CU36: =+BM36 -> 20 | CV36: =+BM36 -> 20 | CW36: =+BQ36 -> 20 | CX36: =+BQ36 -> 20 | CY36: =+BQ36 -> 20 | CZ36: =+BQ36 -> 20 | DA36: =+BU36 -> 20 | DB36: =+BU36 -> 20 | DC36: =+BU36 -> 20 | DD36: =+BU36 -> 20 | DE36: =+BY36 -> 20 | DF36: =+BY36 -> 20 | DG36: =+BY36 -> 20 | DH36: =+BY36 -> 20 | DI36: =+CC36 -> 20 | DJ36: =+CC36 -> 20 | DK36: =+CC36 -> 20 | DL36: =+CC36 -> 20 | DM36: =+CG36 -> 20 | DN36: =+CG36 -> 20 | DO36: =+CG36 -> 20 | DP36: =+CG36 -> 20 | DQ36: =+CK36 -> 20 | DR36: =+CK36 -> 20 | DS36: =+CK36 -> 20 | DT36: =+CK36 -> 20 | DU36: =+CO36 -> 20 | DV36: =+CO36 -> 20 | DW36: =+CO36 -> 20 | DX36: =+CO36 -> 20 | DY36: =+CS36 -> 20 | DZ36: =+CS36 -> 20 | EA36: =+CS36 -> 20 | EB36: =+CS36 -> 20 | EC36: =+CW36 -> 20 | ED36: =+CW36 -> 20 | EE36: =+CW36 -> 20 | EF36: =+CW36 -> 20 | EG36: =+DA36 -> 20 | EH36: =+DA36 -> 20 | EI36: =+DA36 -> 20 | EJ36: =+DA36 -> 20 | EK36: =+DE36 -> 20 | EL36: =+DE36 -> 20 | EM36: =+DE36 -> 20 | EN36: =+DE36 -> 20 | EO36: =+DI36 -> 20 | EP36: =+DI36 -> 20 | EQ36: =+DI36 -> 20 | ER36: =+DI36 -> 20 | ES36: =+DM36 -> 20 | ET36: =+DM36 -> 20 | EU36: =+DM36 -> 20 | EV36: =+DM36 -> 20 | EW36: =SUM(I36:EV36)/4 -> 600 | EX36: 16 | EY36: =24-EX36 -> 8 | EZ36: =+EW36*EX36*28 -> 268800 | FA36: =+EW36*EY36*30 -> 144000
Z39: =+Y39 -> 0 | AA39: =+Z39 -> 0 | AB39: =+AA39 -> 0 | AC39: =+AB39 -> 0 | AD39: =+AC39 -> 0 | AE39: =+AD39 -> 0 | AF39: =+AE39 -> 0
C42: Personnel
C43: Formen | D43: Adet | E43: 6 | AG43: =+E43 -> 6 | AH43: =+E43 -> 6 | AI43: =+E43 -> 6 | AJ43: =+E43 -> 6 | AK43: =+E43 -> 6 | AL43: =+E43 -> 6 | AM43: =+E43 -> 6 | AN43: =+E43 -> 6 | AO43: =+E43 -> 6 | AP43: =+E43 -> 6 | AQ43: =+E43 -> 6 | AR43: =+E43 -> 6 | AS43: =+E43 -> 6 | AT43: =+E43 -> 6 | AU43: =+E43 -> 6 | AV43: =+E43 -> 6 | AW43: =+E43 -> 6 | AX43: =+E43 -> 6 | AY43: =+E43 -> 6 | AZ43: =+E43 -> 6 | BA43: =+E43 -> 6 | BB43: =+E43 -> 6 | BC43: =+E43 -> 6 | BD43: =+E43 -> 6 | BE43: =+E43 -> 6 | BF43: =+E43 -> 6 | BG43: =+E43 -> 6 | BH43: =+E43 -> 6 | BI43: =+E43 -> 6 | BJ43: =+E43 -> 6 | BK43: =+E43 -> 6 | BL43: =+E43 -> 6 | BM43: =+E43 -> 6 | BN43: =+E43 -> 6 | BO43: =+E43 -> 6 | BP43: =+E43 -> 6 | BQ43: =+AK43 -> 6 | BR43: =+AK43 -> 6 | BS43: =+AK43 -> 6 | BT43: =+AK43 -> 6 | BU43: =+AK43 -> 6 | BV43: =+AK43 -> 6 | BW43: =+AK43 -> 6 | BX43: =+AK43 -> 6 | BY43: =+AS43 -> 6 | BZ43: =+AS43 -> 6 | CA43: =+AS43 -> 6 | CB43: =+AS43 -> 6 | CC43: =+AS43 -> 6 | CD43: =+AS43 -> 6 | CE43: =+AS43 -> 6 | CF43: =+AS43 -> 6 | CG43: =+BA43 -> 6 | CH43: =+BA43 -> 6 | CI43: =+BA43 -> 6 | CJ43: =+BA43 -> 6 | CK43: =+BA43 -> 6 | CL43: =+BA43 -> 6 | CM43: =+BA43 -> 6 | CN43: =+BA43 -> 6 | CO43: =+BI43 -> 6 | CP43: =+BI43 -> 6 | CQ43: =+BI43 -> 6 | CR43: =+BI43 -> 6 | CS43: =+BI43 -> 6 | CT43: =+BI43 -> 6 | CU43: =+BI43 -> 6 | CV43: =+BI43 -> 6 | CW43: =+BQ43 -> 6 | CX43: =+BQ43 -> 6 | CY43: =+BQ43 -> 6 | CZ43: =+BQ43 -> 6 | DA43: =+BQ43 -> 6 | DB43: =+BQ43 -> 6 | DC43: =+BQ43 -> 6 | DD43: =+BQ43 -> 6 | DE43: =+BY43 -> 6 | DF43: =+BY43 -> 6 | DG43: =+BY43 -> 6 | DH43: =+BY43 -> 6 | DI43: =+BY43 -> 6 | DJ43: =+BY43 -> 6 | DK43: =+BY43 -> 6 | DL43: =+BY43 -> 6 | DM43: =+CG43 -> 6 | DN43: =+CG43 -> 6 | DO43: =+CG43 -> 6 | DP43: =+CG43 -> 6 | DQ43: =+CG43 -> 6 | DR43: =+CG43 -> 6 | DS43: =+CG43 -> 6 | DT43: =+CG43 -> 6 | DU43: =+CO43 -> 6 | DV43: =+CO43 -> 6 | DW43: =+CO43 -> 6 | DX43: =+CO43 -> 6 | DY43: =+CO43 -> 6 | DZ43: =+CO43 -> 6 | EA43: =+CO43 -> 6 | EB43: =+CO43 -> 6 | EC43: =+CW43 -> 6 | ED43: =+CW43 -> 6 | EE43: =+CW43 -> 6 | EF43: =+CW43 -> 6 | EG43: =+CW43 -> 6 | EH43: =+CW43 -> 6 | EI43: =+CW43 -> 6 | EJ43: =+CW43 -> 6 | EK43: =+DE43 -> 6 | EL43: =+DE43 -> 6 | EM43: =+DE43 -> 6 | EN43: =+DE43 -> 6 | EO43: =+DE43 -> 6 | EP43: =+DE43 -> 6 | EQ43: =+DE43 -> 6 | ER43: =+DE43 -> 6 | ES43: =+DM43 -> 6 | ET43: =+DM43 -> 6 | EU43: =+DM43 -> 6 | EV43: =+DM43 -> 6 | EW43: =SUM(I43:DD43)/4 -> 114
C44: Operator | D44: Adet | E44: 21 | AG44: =+E44 -> 21 | AH44: =+E44 -> 21 | AI44: =+E44 -> 21 | AJ44: =+E44 -> 21 | AK44: =+E44 -> 21 | AL44: =+E44 -> 21 | AM44: =+E44 -> 21 | AN44: =+E44 -> 21 | AO44: =+E44 -> 21 | AP44: =+E44 -> 21 | AQ44: =+E44 -> 21 | AR44: =+E44 -> 21 | AS44: =+E44 -> 21 | AT44: =+E44 -> 21 | AU44: =+E44 -> 21 | AV44: =+E44 -> 21 | AW44: =+E44 -> 21 | AX44: =+E44 -> 21 | AY44: =+E44 -> 21 | AZ44: =+E44 -> 21 | BA44: =+E44 -> 21 | BB44: =+E44 -> 21 | BC44: =+E44 -> 21 | BD44: =+E44 -> 21 | BE44: =+E44 -> 21 | BF44: =+E44 -> 21 | BG44: =+E44 -> 21 | BH44: =+E44 -> 21 | BI44: =+E44 -> 21 | BJ44: =+E44 -> 21 | BK44: =+E44 -> 21 | BL44: =+E44 -> 21 | BM44: =+E44 -> 21 | BN44: =+E44 -> 21 | BO44: =+E44 -> 21 | BP44: =+E44 -> 21 | BQ44: =+AK44 -> 21 | BR44: =+AK44 -> 21 | BS44: =+AK44 -> 21 | BT44: =+AK44 -> 21 | BU44: =+AK44 -> 21 | BV44: =+AK44 -> 21 | BW44: =+AK44 -> 21 | BX44: =+AK44 -> 21 | BY44: =+AS44 -> 21 | BZ44: =+AS44 -> 21 | CA44: =+AS44 -> 21 | CB44: =+AS44 -> 21 | CC44: =+AS44 -> 21 | CD44: =+AS44 -> 21 | CE44: =+AS44 -> 21 | CF44: =+AS44 -> 21 | CG44: =+BA44 -> 21 | CH44: =+BA44 -> 21 | CI44: =+BA44 -> 21 | CJ44: =+BA44 -> 21 | CK44: =+BA44 -> 21 | CL44: =+BA44 -> 21 | CM44: =+BA44 -> 21 | CN44: =+BA44 -> 21 | CO44: =+BI44 -> 21 | CP44: =+BI44 -> 21 | CQ44: =+BI44 -> 21 | CR44: =+BI44 -> 21 | CS44: =+BI44 -> 21 | CT44: =+BI44 -> 21 | CU44: =+BI44 -> 21 | CV44: =+BI44 -> 21 | CW44: =+BQ44 -> 21 | CX44: =+BQ44 -> 21 | CY44: =+BQ44 -> 21 | CZ44: =+BQ44 -> 21 | DA44: =+BQ44 -> 21 | DB44: =+BQ44 -> 21 | DC44: =+BQ44 -> 21 | DD44: =+BQ44 -> 21 | DE44: =+BY44 -> 21 | DF44: =+BY44 -> 21 | DG44: =+BY44 -> 21 | DH44: =+BY44 -> 21 | DI44: =+BY44 -> 21 | DJ44: =+BY44 -> 21 | DK44: =+BY44 -> 21 | DL44: =+BY44 -> 21 | DM44: =+CG44 -> 21 | DN44: =+CG44 -> 21 | DO44: =+CG44 -> 21 | DP44: =+CG44 -> 21 | DQ44: =+CG44 -> 21 | DR44: =+CG44 -> 21 | DS44: =+CG44 -> 21 | DT44: =+CG44 -> 21 | DU44: =+CO44 -> 21 | DV44: =+CO44 -> 21 | DW44: =+CO44 -> 21 | DX44: =+CO44 -> 21 | DY44: =+CO44 -> 21 | DZ44: =+CO44 -> 21 | EA44: =+CO44 -> 21 | EB44: =+CO44 -> 21 | EC44: =+CW44 -> 21 | ED44: =+CW44 -> 21 | EE44: =+CW44 -> 21 | EF44: =+CW44 -> 21 | EG44: =+CW44 -> 21 | EH44: =+CW44 -> 21 | EI44: =+CW44 -> 21 | EJ44: =+CW44 -> 21 | EK44: =+DE44 -> 21 | EL44: =+DE44 -> 21 | EM44: =+DE44 -> 21 | EN44: =+DE44 -> 21 | EO44: =+DE44 -> 21 | EP44: =+DE44 -> 21 | EQ44: =+DE44 -> 21 | ER44: =+DE44 -> 21 | ES44: =+DM44 -> 21 | ET44: =+DM44 -> 21 | EU44: =+DM44 -> 21 | EV44: =+DM44 -> 21 | EW44: =SUM(I44:DD44)/4 -> 399
C45: Kaptan | D45: Adet | E45: 15 | AG45: =+E45 -> 15 | AH45: =+E45 -> 15 | AI45: =+E45 -> 15 | AJ45: =+E45 -> 15 | AK45: =+E45 -> 15 | AL45: =+E45 -> 15 | AM45: =+E45 -> 15 | AN45: =+E45 -> 15 | AO45: =+E45 -> 15 | AP45: =+E45 -> 15 | AQ45: =+E45 -> 15 | AR45: =+E45 -> 15 | AS45: =+E45 -> 15 | AT45: =+E45 -> 15 | AU45: =+E45 -> 15 | AV45: =+E45 -> 15 | AW45: =+E45 -> 15 | AX45: =+E45 -> 15 | AY45: =+E45 -> 15 | AZ45: =+E45 -> 15 | BA45: =+E45 -> 15 | BB45: =+E45 -> 15 | BC45: =+E45 -> 15 | BD45: =+E45 -> 15 | BE45: =+E45 -> 15 | BF45: =+E45 -> 15 | BG45: =+E45 -> 15 | BH45: =+E45 -> 15 | BI45: =+E45 -> 15 | BJ45: =+E45 -> 15 | BK45: =+E45 -> 15 | BL45: =+E45 -> 15 | BM45: =+E45 -> 15 | BN45: =+E45 -> 15 | BO45: =+E45 -> 15 | BP45: =+E45 -> 15 | BQ45: =+AK45 -> 15 | BR45: =+AK45 -> 15 | BS45: =+AK45 -> 15 | BT45: =+AK45 -> 15 | BU45: =+AK45 -> 15 | BV45: =+AK45 -> 15 | BW45: =+AK45 -> 15 | BX45: =+AK45 -> 15 | BY45: =+AS45 -> 15 | BZ45: =+AS45 -> 15 | CA45: =+AS45 -> 15 | CB45: =+AS45 -> 15 | CC45: =+AS45 -> 15 | CD45: =+AS45 -> 15 | CE45: =+AS45 -> 15 | CF45: =+AS45 -> 15 | CG45: =+BA45 -> 15 | CH45: =+BA45 -> 15 | CI45: =+BA45 -> 15 | CJ45: =+BA45 -> 15 | CK45: =+BA45 -> 15 | CL45: =+BA45 -> 15 | CM45: =+BA45 -> 15 | CN45: =+BA45 -> 15 | CO45: =+BI45 -> 15 | CP45: =+BI45 -> 15 | CQ45: =+BI45 -> 15 | CR45: =+BI45 -> 15 | CS45: =+BI45 -> 15 | CT45: =+BI45 -> 15 | CU45: =+BI45 -> 15 | CV45: =+BI45 -> 15 | CW45: =+BQ45 -> 15 | CX45: =+BQ45 -> 15 | CY45: =+BQ45 -> 15 | CZ45: =+BQ45 -> 15 | DA45: =+BQ45 -> 15 | DB45: =+BQ45 -> 15 | DC45: =+BQ45 -> 15 | DD45: =+BQ45 -> 15 | DE45: =+BY45 -> 15 | DF45: =+BY45 -> 15 | DG45: =+BY45 -> 15 | DH45: =+BY45 -> 15 | DI45: =+BY45 -> 15 | DJ45: =+BY45 -> 15 | DK45: =+BY45 -> 15 | DL45: =+BY45 -> 15 | DM45: =+CG45 -> 15 | DN45: =+CG45 -> 15 | DO45: =+CG45 -> 15 | DP45: =+CG45 -> 15 | DQ45: =+CG45 -> 15 | DR45: =+CG45 -> 15 | DS45: =+CG45 -> 15 | DT45: =+CG45 -> 15 | DU45: =+CO45 -> 15 | DV45: =+CO45 -> 15 | DW45: =+CO45 -> 15 | DX45: =+CO45 -> 15 | DY45: =+CO45 -> 15 | DZ45: =+CO45 -> 15 | EA45: =+CO45 -> 15 | EB45: =+CO45 -> 15 | EC45: =+CW45 -> 15 | ED45: =+CW45 -> 15 | EE45: =+CW45 -> 15 | EF45: =+CW45 -> 15 | EG45: =+CW45 -> 15 | EH45: =+CW45 -> 15 | EI45: =+CW45 -> 15 | EJ45: =+CW45 -> 15 | EK45: =+DE45 -> 15 | EL45: =+DE45 -> 15 | EM45: =+DE45 -> 15 | EN45: =+DE45 -> 15 | EO45: =+DE45 -> 15 | EP45: =+DE45 -> 15 | EQ45: =+DE45 -> 15 | ER45: =+DE45 -> 15 | ES45: =+DM45 -> 15 | ET45: =+DM45 -> 15 | EU45: =+DM45 -> 15 | EV45: =+DM45 -> 15 | EW45: =SUM(I45:DD45)/4 -> 285
C46: Çarkçı | D46: Adet | E46: 10 | AG46: =+E46 -> 10 | AH46: =+E46 -> 10 | AI46: =+E46 -> 10 | AJ46: =+E46 -> 10 | AK46: =+E46 -> 10 | AL46: =+E46 -> 10 | AM46: =+E46 -> 10 | AN46: =+E46 -> 10 | AO46: =+E46 -> 10 | AP46: =+E46 -> 10 | AQ46: =+E46 -> 10 | AR46: =+E46 -> 10 | AS46: =+E46 -> 10 | AT46: =+E46 -> 10 | AU46: =+E46 -> 10 | AV46: =+E46 -> 10 | AW46: =+E46 -> 10 | AX46: =+E46 -> 10 | AY46: =+E46 -> 10 | AZ46: =+E46 -> 10 | BA46: =+E46 -> 10 | BB46: =+E46 -> 10 | BC46: =+E46 -> 10 | BD46: =+E46 -> 10 | BE46: =+E46 -> 10 | BF46: =+E46 -> 10 | BG46: =+E46 -> 10 | BH46: =+E46 -> 10 | BI46: =+E46 -> 10 | BJ46: =+E46 -> 10 | BK46: =+E46 -> 10 | BL46: =+E46 -> 10 | BM46: =+E46 -> 10 | BN46: =+E46 -> 10 | BO46: =+E46 -> 10 | BP46: =+E46 -> 10 | BQ46: =+AK46 -> 10 | BR46: =+AK46 -> 10 | BS46: =+AK46 -> 10 | BT46: =+AK46 -> 10 | BU46: =+AK46 -> 10 | BV46: =+AK46 -> 10 | BW46: =+AK46 -> 10 | BX46: =+AK46 -> 10 | BY46: =+AS46 -> 10 | BZ46: =+AS46 -> 10 | CA46: =+AS46 -> 10 | CB46: =+AS46 -> 10 | CC46: =+AS46 -> 10 | CD46: =+AS46 -> 10 | CE46: =+AS46 -> 10 | CF46: =+AS46 -> 10 | CG46: =+BA46 -> 10 | CH46: =+BA46 -> 10 | CI46: =+BA46 -> 10 | CJ46: =+BA46 -> 10 | CK46: =+BA46 -> 10 | CL46: =+BA46 -> 10 | CM46: =+BA46 -> 10 | CN46: =+BA46 -> 10 | CO46: =+BI46 -> 10 | CP46: =+BI46 -> 10 | CQ46: =+BI46 -> 10 | CR46: =+BI46 -> 10 | CS46: =+BI46 -> 10 | CT46: =+BI46 -> 10 | CU46: =+BI46 -> 10 | CV46: =+BI46 -> 10 | CW46: =+BQ46 -> 10 | CX46: =+BQ46 -> 10 | CY46: =+BQ46 -> 10 | CZ46: =+BQ46 -> 10 | DA46: =+BQ46 -> 10 | DB46: =+BQ46 -> 10 | DC46: =+BQ46 -> 10 | DD46: =+BQ46 -> 10 | DE46: =+BY46 -> 10 | DF46: =+BY46 -> 10 | DG46: =+BY46 -> 10 | DH46: =+BY46 -> 10 | DI46: =+BY46 -> 10 | DJ46: =+BY46 -> 10 | DK46: =+BY46 -> 10 | DL46: =+BY46 -> 10 | DM46: =+CG46 -> 10 | DN46: =+CG46 -> 10 | DO46: =+CG46 -> 10 | DP46: =+CG46 -> 10 | DQ46: =+CG46 -> 10 | DR46: =+CG46 -> 10 | DS46: =+CG46 -> 10 | DT46: =+CG46 -> 10 | DU46: =+CO46 -> 10 | DV46: =+CO46 -> 10 | DW46: =+CO46 -> 10 | DX46: =+CO46 -> 10 | DY46: =+CO46 -> 10 | DZ46: =+CO46 -> 10 | EA46: =+CO46 -> 10 | EB46: =+CO46 -> 10 | EC46: =+CW46 -> 10 | ED46: =+CW46 -> 10 | EE46: =+CW46 -> 10 | EF46: =+CW46 -> 10 | EG46: =+CW46 -> 10 | EH46: =+CW46 -> 10 | EI46: =+CW46 -> 10 | EJ46: =+CW46 -> 10 | EK46: =+DE46 -> 10 | EL46: =+DE46 -> 10 | EM46: =+DE46 -> 10 | EN46: =+DE46 -> 10 | EO46: =+DE46 -> 10 | EP46: =+DE46 -> 10 | EQ46: =+DE46 -> 10 | ER46: =+DE46 -> 10 | ES46: =+DM46 -> 10 | ET46: =+DM46 -> 10 | EU46: =+DM46 -> 10 | EV46: =+DM46 -> 10 | EW46: =SUM(I46:DD46)/4 -> 190
